Workbook

Sheet Parámetros
A1: Parámetro | B1: Valor | C1: Unidad
A2: GLOBAL
A3: Total Suministros (Medidores) | B3: 2700000 | C3: unidades
A4: Horizonte de Análisis | B4: 10 | C4: años
A5: WACC del Proyecto | B5: 14.2 | C5: %
A6: Mix Wi-SUN | B6: 20 | C6: %
A7: Mix PLC | B7: 75 | C7: %
A8: Mix Medidores T2/T3 | B8: 2 | C8: %
A9: Rampa Inicial Año 1 | B9: 100000 | C9: unidades
A10: CAPEX — Medidores e Instalación
A11: Costo Medidor T1 | B11: 60 | C11: USD/unidad
A12: Costo Medidor T2/T3 | B12: 100 | C12: USD/unidad
A13: Módulo Comunicación Wi-SUN | B13: 15 | C13: USD/unidad
A14: Módulo Comunicación PLC | B14: 15 | C14: USD/unidad
A15: Módulo Comunicación P2P/Celular | B15: 15 | C15: USD/unidad
A16: Costo Instalación (MO) | B16: 35 | C16: USD/unidad
A17: Logística por Medidor | B17: 5 | C17: USD/unidad
A18: Concentrador PLC | B18: 700 | C18: USD/nodo
A19: Focal Point Wi-SUN | B19: 700 | C19: USD/nodo
A20: Medidores por Concentrador PLC | B20: 250 | C20: und/nodo
A21: Medidores por Focal Point Wi-SUN | B21: 5000 | C21: und/nodo
A22: CAPEX — Plataforma IT
A23: Costo Integración IT Total | B23: 15000000 | C23: USD
A24: Costo Project Management | B24: 1000000 | C24: USD
A25: Desembolso IT Año 0 | B25: 40 | C25: %
A26: Desembolso IT Año 1 | B26: 30 | C26: %
A27: Desembolso IT Año 2 | B27: 20 | C27: %
A28: Desembolso IT Año 3 | B28: 10 | C28: %
A29: OPEX
A30: Mantenimiento IT Anual | B30: 500000 | C30: USD/año
A31: Licencias SaaS Anual | B31: 200000 | C31: USD/año
A32: Administración y Soporte | B32: 500000 | C32: USD/año
A33: Telecomunicaciones (P2P) | B33: 0.52 | C33: USD/med/mes
A34: Cloud Mensual (base) | B34: 5000 | C34: USD/mes
A35: BENEFICIOS — Operacionales
A36: Volumen Lecturas Manuales Anuales | B36: 32400000 | C36: lecturas
A37: Costo Unitario por Lectura | B37: 0.25 | C37: USD/lectura
A38: Cortes Anuales (manual) | B38: 318250 | C38: eventos
A39: Reposiciones Anuales (manual) | B39: 152000 | C39: eventos
A40: Costo Despacho Cuadrilla | B40: 14.6 | C40: USD/visita
...

Sheet Flujo de Fondos
A1: Concepto | B1: Año 0 | C1: Año 1 | D1: Año 2 | E1: Año 3 | F1: Año 4 | G1: Año 5 | H1: Año 6 | I1: Año 7 | J1: Año 8 | K1: Año 9 | L1: Año 10
A4: DESPLIEGUE DE MEDIDORES
A5: └ SM Instalados en el Año | B5: =0 | C5: =Parámetros!$B$9 | D5: =(Parámetros!$B$3-Parámetros!$B$9)/(Parámetros!$B$4-1) | E5: =(Parámetros!$B$3-Parámetros!$B$9)/(Parámetros!$B$4-1) | F5: =(Parámetros!$B$3-Parámetros!$B$9)/(Parámetros!$B$4-1) | G5: =(Parámetros!$B$3-Parámetros!$B$9)/(Parámetros!$B$4-1) | H5: =(Parámetros!$B$3-Parámetros!$B$9)/(Parámetros!$B$4-1) | I5: =(Parámetros!$B$3-Parámetros!$B$9)/(Parámetros!$B$4-1) | J5: =(Parámetros!$B$3-Parámetros!$B$9)/(Parámetros!$B$4-1) | K5: =(Parámetros!$B$3-Parámetros!$B$9)/(Parámetros!$B$4-1) | L5: =(Parámetros!$B$3-Parámetros!$B$9)/(Parámetros!$B$4-1)
A6: └ SM Acumulados (Total Red) | B6: =0 | C6: =SUM(C5:C5) | D6: =SUM(C5:D5) | E6: =SUM(C5:E5) | F6: =SUM(C5:F5) | G6: =SUM(C5:G5) | H6: =SUM(C5:H5) | I6: =SUM(C5:I5) | J6: =SUM(C5:J5) | K6: =SUM(C5:K5) | L6: =SUM(C5:L5)
A7: └ Avance del Despliegue (%) | B7: =0 | C7: =C6/Parámetros!$B$3 | D7: =D6/Parámetros!$B$3 | E7: =E6/Parámetros!$B$3 | F7: =F6/Parámetros!$B$3 | G7: =G6/Parámetros!$B$3 | H7: =H6/Parámetros!$B$3 | I7: =I6/Parámetros!$B$3 | J7: =J6/Parámetros!$B$3 | ... L7: =L6/Parámetros!$B$3
A9: CAPEX — INVERSIÓN
A10: └ CAPEX IT y PM | B10: =Parámetros!$B$25/100*Parámetros!$B$23+Parámetros!$B$24 | C10: =Parámetros!$B$26/100*Parámetros!$B$23 | D10: =Parámetros!$B$27/100*Parámetros!$B$23 | E10: =Parámetros!$B$28/100*Parámetros!$B$23 | F10: =0 | G10: =0 | H10: =0 | I10: =0 | J10: =0 | K10: =0 | L10: =0
A11: └ CAPEX Hardware (Medidores + Módulos Comms) | B11: =0 | C11: =C5*(((1-Parámetros!$B$8/100)*Parámetros!$B$11+(Parámetros!$B$8/100)*Parámetros!$B$12)+((Parámetros!$B$6/100)*Parámetros!$B$13+(Parámetros!$B$7/100)*Parámetros!$B$14+((100-Parámetros!$B$6-Parámetros!$B$7)/100)*Parámetros!$B$15)) | D11: =D5*(((1-Parámetros!$B$8/100)*Parámetros!$B$11+(Parámetros!$B$8/100)*Parámetros!$B$12)+((Parámetros!$B$6/100)*Parámetros!$B$13+(Parámetros!$B$7/100)*Parámetros!$B$14+((100-Parámetros!$B$6-Parámetros!$B$7)/100)*Parámetros!$B$15)) | E11: =E5*(((1-Parámetros!$B$8/100)*Parámetros!$B$11+(Parámetros!$B$8/100)*Parámetros!$B$12)+((Parámetros!$B$6/100)*Parámetros!$B$13+(Parámetros!$B$7/100)*Parámetros!$B$14+((100-Parámetros!$B$6-Parámetros!$B$7)/100)*Parámetros!$B$15)) | F11: =F5*(((1-Parámetros!$B$8/100)*Parámetros!$B$11+(Parámetros!$B$8/100)*Parámetros!$B$12)+((Parámetros!$B$6/100)*Parámetros!$B$13+(Parámetros!$B$7/100)*Parámetros!$B$14+((100-Parámetros!$B$6-Parámetros!$B$7)/100)*Parámetros!$B$15)) | G11: =G5*(((1-Parámetros!$B$8/100)*Parámetros!$B$11+(Parámetros!$B$8/100)*Parámetros!$B$12)+((Parámetros!$B$6/100)*Parámetros!$B$13+(Parámetros!$B$7/100)*Parámetros!$B$14+((100-Parámetros!$B$6-Parámetros!$B$7)/100)*Parámetros!$B$15)) | H11: =H5*(((1-Parámetros!$B$8/100)*Parámetros!$B$11+(Parámetros!$B$8/100)*Parámetros!$B$12)+((Parámetros!$B$6/100)*Parámetros!$B$13+(Parámetros!$B$7/100)*Parámetros!$B$14+((100-Parámetros!$B$6-Parámetros!$B$7)/100)*Parámetros!$B$15)) | I11: =I5*(((1-Parámetros!$B$8/100)*Parámetros!$B$11+(Parámetros!$B$8/100)*Parámetros!$B$12)+((Parámetros!$B$6/100)*Parámetros!$B$13+(Parámetros!$B$7/100)*Parámetros!$B$14+((100-Parámetros!$B$6-Parámetros!$B$7)/100)*Parámetros!$B$15)) | J11: =J5*(((1-Parámetros!$B$8/100)*Parámetros!$B$11+(Parámetros!$B$8/100)*Parámetros!$B$12)+((Parámetros!$B$6/100)*Parámetros!$B$13+(Parámetros!$B$7/100)*Parámetros!$B$14+((100-Parámetros!$B$6-Parámetros!$B$7)/100)*Parámetros!$B$15)) | ... L11: =L5*(((1-Parámetros!$B$8/100)*Parámetros!$B$11+(Parámetros!$B$8/100)*Parámetros!$B$12)+((Parámetros!$B$6/100)*Parámetros!$B$13+(Parámetros!$B$7/100)*Parámetros!$B$14+((100-Parámetros!$B$6-Parámetros!$B$7)/100)*Parámetros!$B$15))
A12: └ CAPEX Instalación y Logística | B12: =0 | C12: =C5*(Parámetros!$B$16+Parámetros!$B$17) | D12: =D5*(Parámetros!$B$16+Parámetros!$B$17) | E12: =E5*(Parámetros!$B$16+Parámetros!$B$17) | F12: =F5*(Parámetros!$B$16+Parámetros!$B$17) | G12: =G5*(Parámetros!$B$16+Parámetros!$B$17) | H12: =H5*(Parámetros!$B$16+Parámetros!$B$17) | I12: =I5*(Parámetros!$B$16+Parámetros!$B$17) | J12: =J5*(Parámetros!$B$16+Parámetros!$B$17) | ... L12: =L5*(Parámetros!$B$16+Parámetros!$B$17)
A13: └ CAPEX Infraestructura (Nodos de Red) | B13: =0 | C13: =(C5*Parámetros!$B$7/100)/Parámetros!$B$20*Parámetros!$B$18+(C5*Parámetros!$B$6/100)/Parámetros!$B$21*Parámetros!$B$19 | D13: =(D5*Parámetros!$B$7/100)/Parámetros!$B$20*Parámetros!$B$18+(D5*Parámetros!$B$6/100)/Parámetros!$B$21*Parámetros!$B$19 | E13: =(E5*Parámetros!$B$7/100)/Parámetros!$B$20*Parámetros!$B$18+(E5*Parámetros!$B$6/100)/Parámetros!$B$21*Parámetros!$B$19 | F13: =(F5*Parámetros!$B$7/100)/Parámetros!$B$20*Parámetros!$B$18+(F5*Parámetros!$B$6/100)/Parámetros!$B$21*Parámetros!$B$19 | G13: =(G5*Parámetros!$B$7/100)/Parámetros!$B$20*Parámetros!$B$18+(G5*Parámetros!$B$6/100)/Parámetros!$B$21*Parámetros!$B$19 | H13: =(H5*Parámetros!$B$7/100)/Parámetros!$B$20*Parámetros!$B$18+(H5*Parámetros!$B$6/100)/Parámetros!$B$21*Parámetros!$B$19 | I13: =(I5*Parámetros!$B$7/100)/Parámetros!$B$20*Parámetros!$B$18+(I5*Parámetros!$B$6/100)/Parámetros!$B$21*Parámetros!$B$19 | J13: =(J5*Parámetros!$B$7/100)/Parámetros!$B$20*Parámetros!$B$18+(J5*Parámetros!$B$6/100)/Parámetros!$B$21*Parámetros!$B$19 | ... L13: =(L5*Parámetros!$B$7/100)/Parámetros!$B$20*Parámetros!$B$18+(L5*Parámetros!$B$6/100)/Parámetros!$B$21*Parámetros!$B$19
A14: CAPEX TOTAL | B14: =B10+B11+B12+B13 | C14: =C10+C11+C12+C13 | D14: =D10+D11+D12+D13 | E14: =E10+E11+E12+E13 | F14: =F10+F11+F12+F13 | G14: =G10+G11+G12+G13 | H14: =H10+H11+H12+H13 | I14: =I10+I11+I12+I13 | ... L14: =L10+L11+L12+L13
A16: OPEX — COSTOS OPERATIVOS
A17: └ Mantenimiento IT | B17: =0 | C17: =Parámetros!$B$30 | D17: =Parámetros!$B$30 | E17: =Parámetros!$B$30 | F17: =Parámetros!$B$30 | G17: =Parámetros!$B$30 | H17: =Parámetros!$B$30 | I17: =Parámetros!$B$30 | J17: =Parámetros!$B$30 | ... L17: =Parámetros!$B$30
A18: └ Licencias SaaS | B18: =0 | C18: =Parámetros!$B$31 | D18: =Parámetros!$B$31 | E18: =Parámetros!$B$31 | F18: =Parámetros!$B$31 | G18: =Parámetros!$B$31 | H18: =Parámetros!$B$31 | I18: =Parámetros!$B$31 | J18: =Parámetros!$B$31 | ... L18: =Parámetros!$B$31
A19: └ Administración y Soporte | B19: =0 | C19: =Parámetros!$B$32 | D19: =Parámetros!$B$32 | E19: =Parámetros!$B$32 | F19: =Parámetros!$B$32 | G19: =Parámetros!$B$32 | H19: =Parámetros!$B$32 | I19: =Parámetros!$B$32 | J19: =Parámetros!$B$32 | ... L19: =Parámetros!$B$32
A20: └ Telecomunicaciones P2P (var. según medidores activos) | B20: =0 | C20: =C6*((100-Parámetros!$B$6-Parámetros!$B$7)/100)*Parámetros!$B$33*12 | D20: =D6*((100-Parámetros!$B$6-Parámetros!$B$7)/100)*Parámetros!$B$33*12 | E20: =E6*((100-Parámetros!$B$6-Parámetros!$B$7)/100)*Parámetros!$B$33*12 | F20: =F6*((100-Parámetros!$B$6-Parámetros!$B$7)/100)*Parámetros!$B$33*12 | G20: =G6*((100-Parámetros!$B$6-Parámetros!$B$7)/100)*Parámetros!$B$33*12 | H20: =H6*((100-Parámetros!$B$6-Parámetros!$B$7)/100)*Parámetros!$B$33*12 | I20: =I6*((100-Parámetros!$B$6-Parámetros!$B$7)/100)*Parámetros!$B$33*12 | J20: =J6*((100-Parámetros!$B$6-Parámetros!$B$7)/100)*Parámetros!$B$33*12 | ... L20: =L6*((100-Parámetros!$B$6-Parámetros!$B$7)/100)*Parámetros!$B$33*12
A21: └ Cloud Mensual (base fija) | B21: =0 | C21: =Parámetros!$B$34*12 | D21: =Parámetros!$B$34*12 | E21: =Parámetros!$B$34*12 | F21: =Parámetros!$B$34*12 | G21: =Parámetros!$B$34*12 | H21: =Parámetros!$B$34*12 | I21: =Parámetros!$B$34*12 | J21: =Parámetros!$B$34*12 | ... L21: =Parámetros!$B$34*12
A22: OPEX TOTAL | B22: =B17+B18+B19+B20+B21 | C22: =C17+C18+C19+C20+C21 | D22: =D17+D18+D19+D20+D21 | E22: =E17+E18+E19+E20+E21 | F22: =F17+F18+F19+F20+F21 | G22: =G17+G18+G19+G20+G21 | H22: =H17+H18+H19+H20+H21 | I22: =I17+I18+I19+I20+I21 | ... L22: =L17+L18+L19+L20+L21
A24: BENEFICIOS — SAVINGS OPERACIONALES Y REGULATORIOS
A25: └ Lecturas Manuales Evitadas | B25: =0 | C25: =Parámetros!$B$36*Parámetros!$B$37*C7 | D25: =Parámetros!$B$36*Parámetros!$B$37*D7 | E25: =Parámetros!$B$36*Parámetros!$B$37*E7 | F25: =Parámetros!$B$36*Parámetros!$B$37*F7 | G25: =Parámetros!$B$36*Parámetros!$B$37*G7 | H25: =Parámetros!$B$36*Parámetros!$B$37*H7 | I25: =Parámetros!$B$36*Parámetros!$B$37*I7 | J25: =Parámetros!$B$36*Parámetros!$B$37*J7 | ... L25: =Parámetros!$B$36*Parámetros!$B$37*L7
A26: └ Cortes y Reposiciones Remotas (cuadrilla evitada) | B26: =0 | C26: =(Parámetros!$B$38+Parámetros!$B$39)*Parámetros!$B$40*C7 | D26: =(Parámetros!$B$38+Parámetros!$B$39)*Parámetros!$B$40*D7 | E26: =(Parámetros!$B$38+Parámetros!$B$39)*Parámetros!$B$40*E7 | F26: =(Parámetros!$B$38+Parámetros!$B$39)*Parámetros!$B$40*F7 | G26: =(Parámetros!$B$38+Parámetros!$B$39)*Parámetros!$B$40*G7 | H26: =(Parámetros!$B$38+Parámetros!$B$39)*Parámetros!$B$40*H7 | I26: =(Parámetros!$B$38+Parámetros!$B$39)*Parámetros!$B$40*I7 | J26: =(Parámetros!$B$38+Parámetros!$B$39)*Parámetros!$B$40*J7 | ... L26: =(Parámetros!$B$38+Parámetros!$B$39)*Parámetros!$B$40*L7
A27: └ Visitas Improductivas, Reiterativas y de Calidad Evitadas | B27: =0 | C27: =(Parámetros!$B$41+Parámetros!$B$42+Parámetros!$B$43)*Parámetros!$B$44*C7 | D27: =(Parámetros!$B$41+Parámetros!$B$42+Parámetros!$B$43)*Parámetros!$B$44*D7 | E27: =(Parámetros!$B$41+Parámetros!$B$42+Parámetros!$B$43)*Parámetros!$B$44*E7 | F27: =(Parámetros!$B$41+Parámetros!$B$42+Parámetros!$B$43)*Parámetros!$B$44*F7 | G27: =(Parámetros!$B$41+Parámetros!$B$42+Parámetros!$B$43)*Parámetros!$B$44*G7 | H27: =(Parámetros!$B$41+Parámetros!$B$42+Parámetros!$B$43)*Parámetros!$B$44*H7 | I27: =(Parámetros!$B$41+Parámetros!$B$42+Parámetros!$B$43)*Parámetros!$B$44*I7 | J27: =(Parámetros!$B$41+Parámetros!$B$42+Parámetros!$B$43)*Parámetros!$B$44*J7 | ... L27: =(Parámetros!$B$41+Parámetros!$B$42+Parámetros!$B$43)*Parámetros!$B$44*L7
A28: └ Reducción Multas SAIDI (minutos × penalidad) | B28: =0 | C28: =Parámetros!$B$46*(Parámetros!$B$47/100)*Parámetros!$B$48*C7 | D28: =Parámetros!$B$46*(Parámetros!$B$47/100)*Parámetros!$B$48*D7 | E28: =Parámetros!$B$46*(Parámetros!$B$47/100)*Parámetros!$B$48*E7 | F28: =Parámetros!$B$46*(Parámetros!$B$47/100)*Parámetros!$B$48*F7 | G28: =Parámetros!$B$46*(Parámetros!$B$47/100)*Parámetros!$B$48*G7 | H28: =Parámetros!$B$46*(Parámetros!$B$47/100)*Parámetros!$B$48*H7 | I28: =Parámetros!$B$46*(Parámetros!$B$47/100)*Parámetros!$B$48*I7 | J28: =Parámetros!$B$46*(Parámetros!$B$47/100)*Parámetros!$B$48*J7 | ... L28: =Parámetros!$B$46*(Parámetros!$B$47/100)*Parámetros!$B$48*L7
A29: └ Reducción Multas por Estimación (lectura real evita sanción) | B29: =0 | C29: =Parámetros!$B$49*C7 | D29: =Parámetros!$B$49*D7 | E29: =Parámetros!$B$49*E7 | F29: =Parámetros!$B$49*F7 | G29: =Parámetros!$B$49*G7 | H29: =Parámetros!$B$49*H7 | I29: =Parámetros!$B$49*I7 | J29: =Parámetros!$B$49*J7 | ... L29: =Parámetros!$B$49*L7
A30: └ Reducción Multas de Apartamiento (Calidad de Producto) | B30: =0 | C30: =Parámetros!$B$50*(Parámetros!$B$51/100)*C7 | D30: =Parámetros!$B$50*(Parámetros!$B$51/100)*D7 | E30: =Parámetros!$B$50*(Parámetros!$B$51/100)*E7 | F30: =Parámetros!$B$50*(Parámetros!$B$51/100)*F7 | G30: =Parámetros!$B$50*(Parámetros!$B$51/100)*G7 | H30: =Parámetros!$B$50*(Parámetros!$B$51/100)*H7 | I30: =Parámetros!$B$50*(Parámetros!$B$51/100)*I7 | J30: =Parámetros!$B$50*(Parámetros!$B$51/100)*J7 | ... L30: =Parámetros!$B$50*(Parámetros!$B$51/100)*L7
A31: └ Reducción Multas de Incumplimiento Regulatorio | B31: =0 | C31: =Parámetros!$B$52*(Parámetros!$B$53/100)*C7 | D31: =Parámetros!$B$52*(Parámetros!$B$53/100)*D7 | E31: =Parámetros!$B$52*(Parámetros!$B$53/100)*E7 | F31: =Parámetros!$B$52*(Parámetros!$B$53/100)*F7 | G31: =Parámetros!$B$52*(Parámetros!$B$53/100)*G7 | H31: =Parámetros!$B$52*(Parámetros!$B$53/100)*H7 | I31: =Parámetros!$B$52*(Parámetros!$B$53/100)*I7 | J31: =Parámetros!$B$52*(Parámetros!$B$53/100)*J7 | ... L31: =Parámetros!$B$52*(Parámetros!$B$53/100)*L7
A32: └ Reducción Reclamos y Llamadas Call Center | B32: =0 | C32: =(Parámetros!$B$55+Parámetros!$B$56)*Parámetros!$B$57*C7 | D32: =(Parámetros!$B$55+Parámetros!$B$56)*Parámetros!$B$57*D7 | E32: =(Parámetros!$B$55+Parámetros!$B$56)*Parámetros!$B$57*E7 | F32: =(Parámetros!$B$55+Parámetros!$B$56)*Parámetros!$B$57*F7 | G32: =(Parámetros!$B$55+Parámetros!$B$56)*Parámetros!$B$57*G7 | H32: =(Parámetros!$B$55+Parámetros!$B$56)*Parámetros!$B$57*H7 | I32: =(Parámetros!$B$55+Parámetros!$B$56)*Parámetros!$B$57*I7 | J32: =(Parámetros!$B$55+Parámetros!$B$56)*Parámetros!$B$57*J7 | ... L32: =(Parámetros!$B$55+Parámetros!$B$56)*Parámetros!$B$57*L7
A33: └ Reducción Resarcimientos por Artefactos Quemados | B33: =0 | C33: =Parámetros!$B$58*(Parámetros!$B$59/100)*C7 | D33: =Parámetros!$B$58*(Parámetros!$B$59/100)*D7 | E33: =Parámetros!$B$58*(Parámetros!$B$59/100)*E7 | F33: =Parámetros!$B$58*(Parámetros!$B$59/100)*F7 | G33: =Parámetros!$B$58*(Parámetros!$B$59/100)*G7 | H33: =Parámetros!$B$58*(Parámetros!$B$59/100)*H7 | I33: =Parámetros!$B$58*(Parámetros!$B$59/100)*I7 | J33: =Parámetros!$B$58*(Parámetros!$B$59/100)*J7 | ... L33: =Parámetros!$B$58*(Parámetros!$B$59/100)*L7
A34: └ Recupero de Pérdidas No Técnicas / Fraude | B34: =0 | C34: =Parámetros!$B$61*(Parámetros!$B$62/100)*(Parámetros!$B$64-Parámetros!$B$63)*C7 | D34: =Parámetros!$B$61*(Parámetros!$B$62/100)*(Parámetros!$B$64-Parámetros!$B$63)*D7 | E34: =Parámetros!$B$61*(Parámetros!$B$62/100)*(Parámetros!$B$64-Parámetros!$B$63)*E7 | F34: =Parámetros!$B$61*(Parámetros!$B$62/100)*(Parámetros!$B$64-Parámetros!$B$63)*F7 | G34: =Parámetros!$B$61*(Parámetros!$B$62/100)*(Parámetros!$B$64-Parámetros!$B$63)*G7 | H34: =Parámetros!$B$61*(Parámetros!$B$62/100)*(Parámetros!$B$64-Parámetros!$B$63)*H7 | I34: =Parámetros!$B$61*(Parámetros!$B$62/100)*(Parámetros!$B$64-Parámetros!$B$63)*I7 | J34: =Parámetros!$B$61*(Parámetros!$B$62/100)*(Parámetros!$B$64-Parámetros!$B$63)*J7 | ... L34: =Parámetros!$B$61*(Parámetros!$B$62/100)*(Parámetros!$B$64-Parámetros!$B$63)*L7
A35: BENEFICIOS TOTALES | B35: =B25+B26+B27+B28+B29+B30+B31+B32+B33+B34 | C35: =C25+C26+C27+C28+C29+C30+C31+C32+C33+C34 | D35: =D25+D26+D27+D28+D29+D30+D31+D32+D33+D34 | E35: =E25+E26+E27+E28+E29+E30+E31+E32+E33+E34 | F35: =F25+F26+F27+F28+F29+F30+F31+F32+F33+F34 | G35: =G25+G26+G27+G28+G29+G30+G31+G32+G33+G34 | H35: =H25+H26+H27+H28+H29+H30+H31+H32+H33+H34 | I35: =I25+I26+I27+I28+I29+I30+I31+I32+I33+I34 | ... L35: =L25+L26+L27+L28+L29+L30+L31+L32+L33+L34
A37: INGRESOS VAD — RECONOCIMIENTO TARIFARIO ENRE
A38: └ VAD IT (Amortización + Retorno sobre RAB — Plataforma) | B38: =(MAX(0,Parámetros!$B$25/100*Parámetros!$B$23-Parámetros!$B$70)/Parámetros!$B$69+(MAX(0,Parámetros!$B$25/100*Parámetros!$B$23-Parámetros!$B$70)-MAX(0,Parámetros!$B$25/100*Parámetros!$B$23-Parámetros!$B$70)*0/Parámetros!$B$69)*Parámetros!$B$66/100) | C38: =(MAX(0,Parámetros!$B$25/100*Parámetros!$B$23-Parámetros!$B$70)/Parámetros!$B$69+(MAX(0,Parámetros!$B$25/100*Parámetros!$B$23-Parámetros!$B$70)-MAX(0,Parámetros!$B$25/100*Parámetros!$B$23-Parámetros!$B$70)*1/Parámetros!$B$69)*Parámetros!$B$66/100)+(Parámetros!$B$26/100*Parámetros!$B$23/Parámetros!$B$69+(Parámetros!$B$26/100*Parámetros!$B$23-Parámetros!$B$26/100*Parámetros!$B$23*0/Parámetros!$B$69)*Parámetros!$B$66/100) | D38: =(MAX(0,Parámetros!$B$25/100*Parámetros!$B$23-Parámetros!$B$70)/Parámetros!$B$69+(MAX(0,Parámetros!$B$25/100*Parámetros!$B$23-Parámetros!$B$70)-MAX(0,Parámetros!$B$25/100*Parámetros!$B$23-Parámetros!$B$70)*2/Parámetros!$B$69)*Parámetros!$B$66/100)+(Parámetros!$B$26/100*Parámetros!$B$23/Parámetros!$B$69+(Parámetros!$B$26/100*Parámetros!$B$23-Parámetros!$B$26/100*Parámetros!$B$23*1/Parámetros!$B$69)*Parámetros!$B$66/100)+(Parámetros!$B$27/100*Parámetros!$B$23/Parámetros!$B$69+(Parámetros!$B$27/100*Parámetros!$B$23-Parámetros!$B$27/100*Parámetros!$B$23*0/Parámetros!$B$69)*Parámetros!$B$66/100) | E38: =(MAX(0,Parámetros!$B$25/100*Parámetros!$B$23-Parámetros!$B$70)/Parámetros!$B$69+(MAX(0,Parámetros!$B$25/100*Parámetros!$B$23-Parámetros!$B$70)-MAX(0,Parámetros!$B$25/100*Parámetros!$B$23-Parámetros!$B$70)*3/Parámetros!$B$69)*Parámetros!$B$66/100)+(Parámetros!$B$26/100*Parámetros!$B$23/Parámetros!$B$69+(Parámetros!$B$26/100*Parámetros!$B$23-Parámetros!$B$26/100*Parámetros!$B$23*2/Parámetros!$B$69)*Parámetros!$B$66/100)+(Parámetros!$B$27/100*Parámetros!$B$23/Parámetros!$B$69+(Parámetros!$B$27/100*Parámetros!$B$23-Parámetros!$B$27/100*Parámetros!$B$23*1/Parámetros!$B$69)*Parámetros!$B$66/100)+(Parámetros!$B$28/100*Parámetros!$B$23/Parámetros!$B$69+(Parámetros!$B$28/100*Parámetros!$B$23-Parámetros!$B$28/100*Parámetros!$B$23*0/Parámetros!$B$69)*Parámetros!$B$66/100) | F38: =(MAX(0,Parámetros!$B$25/100*Parámetros!$B$23-Parámetros!$B$70)/Parámetros!$B$69+(MAX(0,Parámetros!$B$25/100*Parámetros!$B$23-Parámetros!$B$70)-MAX(0,Parámetros!$B$25/100*Parámetros!$B$23-Parámetros!$B$70)*4/Parámetros!$B$69)*Parámetros!$B$66/100)+(Parámetros!$B$26/100*Parámetros!$B$23/Parámetros!$B$69+(Parámetros!$B$26/100*Parámetros!$B$23-Parámetros!$B$26/100*Parámetros!$B$23*3/Parámetros!$B$69)*Parámetros!$B$66/100)+(Parámetros!$B$27/100*Parámetros!$B$23/Parámetros!$B$69+(Parámetros!$B$27/100*Parámetros!$B$23-Parámetros!$B$27/100*Parámetros!$B$23*2/Parámetros!$B$69)*Parámetros!$B$66/100)+(Parámetros!$B$28/100*Parámetros!$B$23/Parámetros!$B$69+(Parámetros!$B$28/100*Parámetros!$B$23-Parámetros!$B$28/100*Parámetros!$B$23*1/Parámetros!$B$69)*Parámetros!$B$66/100) | G38: =(MAX(0,Parámetros!$B$25/100*Parámetros!$B$23-Parámetros!$B$70)/Parámetros!$B$69+(MAX(0,Parámetros!$B$25/100*Parámetros!$B$23-Parámetros!$B$70)-MAX(0,Parámetros!$B$25/100*Parámetros!$B$23-Parámetros!$B$70)*5/Parámetros!$B$69)*Parámetros!$B$66/100)+(Parámetros!$B$26/100*Parámetros!$B$23/Parámetros!$B$69+(Parámetros!$B$26/100*Parámetros!$B$23-Parámetros!$B$26/100*Parámetros!$B$23*4/Parámetros!$B$69)*Parámetros!$B$66/100)+(Parámetros!$B$27/100*Parámetros!$B$23/Parámetros!$B$69+(Parámetros!$B$27/100*Parámetros!$B$23-Parámetros!$B$27/100*Parámetros!$B$23*3/Parámetros!$B$69)*Parámetros!$B$66/100)+(Parámetros!$B$28/100*Parámetros!$B$23/Parámetros!$B$69+(Parámetros!$B$28/100*Parámetros!$B$23-Parámetros!$B$28/100*Parámetros!$B$23*2/Parámetros!$B$69)*Parámetros!$B$66/100) | H38: =(MAX(0,Parámetros!$B$25/100*Parámetros!$B$23-Parámetros!$B$70)/Parámetros!$B$69+(MAX(0,Parámetros!$B$25/100*Parámetros!$B$23-Parámetros!$B$70)-MAX(0,Parámetros!$B$25/100*Parámetros!$B$23-Parámetros!$B$70)*6/Parámetros!$B$69)*Parámetros!$B$66/100)+(Parámetros!$B$26/100*Parámetros!$B$23/Parámetros!$B$69+(Parámetros!$B$26/100*Parámetros!$B$23-Parámetros!$B$26/100*Parámetros!$B$23*5/Parámetros!$B$69)*Parámetros!$B$66/100)+(Parámetros!$B$27/100*Parámetros!$B$23/Parámetros!$B$69+(Parámetros!$B$27/100*Parámetros!$B$23-Parámetros!$B$27/100*Parámetros!$B$23*4/Parámetros!$B$69)*Parámetros!$B$66/100)+(Parámetros!$B$28/100*Parámetros!$B$23/Parámetros!$B$69+(Parámetros!$B$28/100*Parámetros!$B$23-Parámetros!$B$28/100*Parámetros!$B$23*3/Parámetros!$B$69)*Parámetros!$B$66/100) | I38: =(MAX(0,Parámetros!$B$25/100*Parámetros!$B$23-Parámetros!$B$70)/Parámetros!$B$69+(MAX(0,Parámetros!$B$25/100*Parámetros!$B$23-Parámetros!$B$70)-MAX(0,Parámetros!$B$25/100*Parámetros!$B$23-Parámetros!$B$70)*7/Parámetros!$B$69)*Parámetros!$B$66/100)+(Parámetros!$B$26/100*Parámetros!$B$23/Parámetros!$B$69+(Parámetros!$B$26/100*Parámetros!$B$23-Parámetros!$B$26/100*Parámetros!$B$23*6/Parámetros!$B$69)*Parámetros!$B$66/100)+(Parámetros!$B$27/100*Parámetros!$B$23/Parámetros!$B$69+(Parámetros!$B$27/100*Parámetros!$B$23-Parámetros!$B$27/100*Parámetros!$B$23*5/Parámetros!$B$69)*Parámetros!$B$66/100)+(Parámetros!$B$28/100*Parámetros!$B$23/Parámetros!$B$69+(Parámetros!$B$28/100*Parámetros!$B$23-Parámetros!$B$28/100*Parámetros!$B$23*4/Parámetros!$B$69)*Parámetros!$B$66/100) | J38: =(MAX(0,Parámetros!$B$25/100*Parámetros!$B$23-Parámetros!$B$70)/Parámetros!$B$69+(MAX(0,Parámetros!$B$25/100*Parámetros!$B$23-Parámetros!$B$70)-MAX(0,Parámetros!$B$25/100*Parámetros!$B$23-Parámetros!$B$70)*8/Parámetros!$B$69)*Parámetros!$B$66/100)+(Parámetros!$B$26/100*Parámetros!$B$23/Parámetros!$B$69+(Parámetros!$B$26/100*Parámetros!$B$23-Parámetros!$B$26/100*Parámetros!$B$23*7/Parámetros!$B$69)*Parámetros!$B$66/100)+(Parámetros!$B$27/100*Parámetros!$B$23/Parámetros!$B$69+(Parámetros!$B$27/100*Parámetros!$B$23-Parámetros!$B$27/100*Parámetros!$B$23*6/Parámetros!$B$69)*Parámetros!$B$66/100)+(Parámetros!$B$28/100*Parámetros!$B$23/Parámetros!$B$69+(Parámetros!$B$28/100*Parámetros!$B$23-Parámetros!$B$28/100*Parámetros!$B$23*5/Parámetros!$B$69)*Parámetros!$B$66/100) | K38: =(MAX(0,Parámetros!$B$25/100*Parámetros!$B$23-Parámetros!$B$70)/Parámetros!$B$69+(MAX(0,Parámetros!$B$25/100*Parámetros!$B$23-Parámetros!$B$70)-MAX(0,Parámetros!$B$25/100*Parámetros!$B$23-Parámetros!$B$70)*9/Parámetros!$B$69)*Parámetros!$B$66/100)+(Parámetros!$B$26/100*Parámetros!$B$23/Parámetros!$B$69+(Parámetros!$B$26/100*Parámetros!$B$23-Parámetros!$B$26/100*Parámetros!$B$23*8/Parámetros!$B$69)*Parámetros!$B$66/100)+(Parámetros!$B$27/100*Parámetros!$B$23/Parámetros!$B$69+(Parámetros!$B$27/100*Parámetros!$B$23-Parámetros!$B$27/100*Parámetros!$B$23*7/Parámetros!$B$69)*Parámetros!$B$66/100)+(Parámetros!$B$28/100*Parámetros!$B$23/Parámetros!$B$69+(Parámetros!$B$28/100*Parámetros!$B$23-Parámetros!$B$28/100*Parámetros!$B$23*6/Parámetros!$B$69)*Parámetros!$B$66/100) | L38: =(Parámetros!$B$26/100*Parámetros!$B$23/Parámetros!$B$69+(Parámetros!$B$26/100*Parámetros!$B$23-Parámetros!$B$26/100*Parámetros!$B$23*9/Parámetros!$B$69)*Parámetros!$B$66/100)+(Parámetros!$B$27/100*Parámetros!$B$23/Parámetros!$B$69+(Parámetros!$B$27/100*Parámetros!$B$23-Parámetros!$B$27/100*Parámetros!$B$23*8/Parámetros!$B$69)*Parámetros!$B$66/100)+(Parámetros!$B$28/100*Parámetros!$B$23/Parámetros!$B$69+(Parámetros!$B$28/100*Parámetros!$B$23-Parámetros!$B$28/100*Parámetros!$B$23*7/Parámetros!$B$69)*Parámetros!$B$66/100)
A39: └ VAD Medidores (Amortización + Retorno sobre RAB — por Cohorte) | B39: =0 | C39: =(C5*Parámetros!$B$67/Parámetros!$B$68+(C5*Parámetros!$B$67-C5*Parámetros!$B$67*0/Parámetros!$B$68)*Parámetros!$B$66/100) | D39: =(C5*Parámetros!$B$67/Parámetros!$B$68+(C5*Parámetros!$B$67-C5*Parámetros!$B$67*1/Parámetros!$B$68)*Parámetros!$B$66/100)+(D5*Parámetros!$B$67/Parámetros!$B$68+(D5*Parámetros!$B$67-D5*Parámetros!$B$67*0/Parámetros!$B$68)*Parámetros!$B$66/100) | E39: =(C5*Parámetros!$B$67/Parámetros!$B$68+(C5*Parámetros!$B$67-C5*Parámetros!$B$67*2/Parámetros!$B$68)*Parámetros!$B$66/100)+(D5*Parámetros!$B$67/Parámetros!$B$68+(D5*Parámetros!$B$67-D5*Parámetros!$B$67*1/Parámetros!$B$68)*Parámetros!$B$66/100)+(E5*Parámetros!$B$67/Parámetros!$B$68+(E5*Parámetros!$B$67-E5*Parámetros!$B$67*0/Parámetros!$B$68)*Parámetros!$B$66/100) | F39: =(C5*Parámetros!$B$67/Parámetros!$B$68+(C5*Parámetros!$B$67-C5*Parámetros!$B$67*3/Parámetros!$B$68)*Parámetros!$B$66/100)+(D5*Parámetros!$B$67/Parámetros!$B$68+(D5*Parámetros!$B$67-D5*Parámetros!$B$67*2/Parámetros!$B$68)*Parámetros!$B$66/100)+(E5*Parámetros!$B$67/Parámetros!$B$68+(E5*Parámetros!$B$67-E5*Parámetros!$B$67*1/Parámetros!$B$68)*Parámetros!$B$66/100)+(F5*(((1-Parámetros!$B$8/100)*Parámetros!$B$11+(Parámetros!$B$8/100)*Parámetros!$B$12)+((Parámetros!$B$6/100)*Parámetros!$B$13+(Parámetros!$B$7/100)*Parámetros!$B$14+((100-Parámetros!$B$6-Parámetros!$B$7)/100)*Parámetros!$B$15)+Parámetros!$B$16)/Parámetros!$B$68+(F5*(((1-Parámetros!$B$8/100)*Parámetros!$B$11+(Parámetros!$B$8/100)*Parámetros!$B$12)+((Parámetros!$B$6/100)*Parámetros!$B$13+(Parámetros!$B$7/100)*Parámetros!$B$14+((100-Parámetros!$B$6-Parámetros!$B$7)/100)*Parámetros!$B$15)+Parámetros!$B$16)-F5*(((1-Parámetros!$B$8/100)*Parámetros!$B$11+(Parámetros!$B$8/100)*Parámetros!$B$12)+((Parámetros!$B$6/100)*Parámetros!$B$13+(Parámetros!$B$7/100)*Parámetros!$B$14+((100-Parámetros!$B$6-Parámetros!$B$7)/100)*Parámetros!$B$15)+Parámetros!$B$16)*0/Parámetros!$B$68)*Parámetros!$B$66/100) | G39: =(C5*Parámetros!$B$67/Parámetros!$B$68+(C5*Parámetros!$B$67-C5*Parámetros!$B$67*4/Parámetros!$B$68)*Parámetros!$B$66/100)+(D5*Parámetros!$B$67/Parámetros!$B$68+(D5*Parámetros!$B$67-D5*Parámetros!$B$67*3/Parámetros!$B$68)*Parámetros!$B$66/100)+(E5*Parámetros!$B$67/Parámetros!$B$68+(E5*Parámetros!$B$67-E5*Parámetros!$B$67*2/Parámetros!$B$68)*Parámetros!$B$66/100)+(F5*(((1-Parámetros!$B$8/100)*Parámetros!$B$11+(Parámetros!$B$8/100)*Parámetros!$B$12)+((Parámetros!$B$6/100)*Parámetros!$B$13+(Parámetros!$B$7/100)*Parámetros!$B$14+((100-Parámetros!$B$6-Parámetros!$B$7)/100)*Parámetros!$B$15)+Parámetros!$B$16)/Parámetros!$B$68+(F5*(((1-Parámetros!$B$8/100)*Parámetros!$B$11+(Parámetros!$B$8/100)*Parámetros!$B$12)+((Parámetros!$B$6/100)*Parámetros!$B$13+(Parámetros!$B$7/100)*Parámetros!$B$14+((100-Parámetros!$B$6-Parámetros!$B$7)/100)*Parámetros!$B$15)+Parámetros!$B$16)-F5*(((1-Parámetros!$B$8/100)*Parámetros!$B$11+(Parámetros!$B$8/100)*Parámetros!$B$12)+((Parámetros!$B$6/100)*Parámetros!$B$13+(Parámetros!$B$7/100)*Parámetros!$B$14+((100-Parámetros!$B$6-Parámetros!$B$7)/100)*Parámetros!$B$15)+Parámetros!$B$16)*1/Parámetros!$B$68)*Parámetros!$B$66/100)+(G5*(((1-Parámetros!$B$8/100)*Parámetros!$B$11+(Parámetros!$B$8/100)*Parámetros!$B$12)+((Parámetros!$B$6/100)*Parámetros!$B$13+(Parámetros!$B$7/100)*Parámetros!$B$14+((100-Parámetros!$B$6-Parámetros!$B$7)/100)*Parámetros!$B$15)+Parámetros!$B$16)/Parámetros!$B$68+(G5*(((1-Parámetros!$B$8/100)*Parámetros!$B$11+(Parámetros!$B$8/100)*Parámetros!$B$12)+((Parámetros!$B$6/100)*Parámetros!$B$13+(Parámetros!$B$7/100)*Parámetros!$B$14+((100-Parámetros!$B$6-Parámetros!$B$7)/100)*Parámetros!$B$15)+Parámetros!$B$16)-G5*(((1-Parámetros!$B$8/100)*Parámetros!$B$11+(Parámetros!$B$8/100)*Parámetros!$B$12)+((Parámetros!$B$6/100)*Parámetros!$B$13+(Parámetros!$B$7/100)*Parámetros!$B$14+((100-Parámetros!$B$6-Parámetros!$B$7)/100)*Parámetros!$B$15)+Parámetros!$B$16)*0/Parámetros!$B$68)*Parámetros!$B$66/100) | H39: =(C5*Parámetros!$B$67/Parámetros!$B$68+(C5*Parámetros!$B$67-C5*Parámetros!$B$67*5/Parámetros!$B$68)*Parámetros!$B$66/100)+(D5*Parámetros!$B$67/Parámetros!$B$68+(D5*Parámetros!$B$67-D5*Parámetros!$B$67*4/Parámetros!$B$68)*Parámetros!$B$66/100)+(E5*Parámetros!$B$67/Parámetros!$B$68+(E5*Parámetros!$B$67-E5*Parámetros!$B$67*3/Parámetros!$B$68)*Parámetros!$B$66/100)+(F5*(((1-Parámetros!$B$8/100)*Parámetros!$B$11+(Parámetros!$B$8/100)*Parámetros!$B$12)+((Parámetros!$B$6/100)*Parámetros!$B$13+(Parámetros!$B$7/100)*Parámetros!$B$14+((100-Parámetros!$B$6-Parámetros!$B$7)/100)*Parámetros!$B$15)+Parámetros!$B$16)/Parámetros!$B$68+(F5*(((1-Parámetros!$B$8/100)*Parámetros!$B$11+(Parámetros!$B$8/100)*Parámetros!$B$12)+((Parámetros!$B$6/100)*Parámetros!$B$13+(Parámetros!$B$7/100)*Parámetros!$B$14+((100-Parámetros!$B$6-Parámetros!$B$7)/100)*Parámetros!$B$15)+Parámetros!$B$16)-F5*(((1-Parámetros!$B$8/100)*Parámetros!$B$11+(Parámetros!$B$8/100)*Parámetros!$B$12)+((Parámetros!$B$6/100)*Parámetros!$B$13+(Parámetros!$B$7/100)*Parámetros!$B$14+((100-Parámetros!$B$6-Parámetros!$B$7)/100)*Parámetros!$B$15)+Parámetros!$B$16)*2/Parámetros!$B$68)*Parámetros!$B$66/100)+(G5*(((1-Parámetros!$B$8/100)*Parámetros!$B$11+(Parámetros!$B$8/100)*Parámetros!$B$12)+((Parámetros!$B$6/100)*Parámetros!$B$13+(Parámetros!$B$7/100)*Parámetros!$B$14+((100-Parámetros!$B$6-Parámetros!$B$7)/100)*Parámetros!$B$15)+Parámetros!$B$16)/Parámetros!$B$68+(G5*(((1-Parámetros!$B$8/100)*Parámetros!$B$11+(Parámetros!$B$8/100)*Parámetros!$B$12)+((Parámetros!$B$6/100)*Parámetros!$B$13+(Parámetros!$B$7/100)*Parámetros!$B$14+((100-Parámetros!$B$6-Parámetros!$B$7)/100)*Parámetros!$B$15)+Parámetros!$B$16)-G5*(((1-Parámetros!$B$8/100)*Parámetros!$B$11+(Parámetros!$B$8/100)*Parámetros!$B$12)+((Parámetros!$B$6/100)*Parámetros!$B$13+(Parámetros!$B$7/100)*Parámetros!$B$14+((100-Parámetros!$B$6-Parámetros!$B$7)/100)*Parámetros!$B$15)+Parámetros!$B$16)*1/Parámetros!$B$68)*Parámetros!$B$66/100)+(H5*(((1-Parámetros!$B$8/100)*Parámetros!$B$11+(Parámetros!$B$8/100)*Parámetros!$B$12)+((Parámetros!$B$6/100)*Parámetros!$B$13+(Parámetros!$B$7/100)*Parámetros!$B$14+((100-Parámetros!$B$6-Parámetros!$B$7)/100)*Parámetros!$B$15)+Parámetros!$B$16)/Parámetros!$B$68+(H5*(((1-Parámetros!$B$8/100)*Parámetros!$B$11+(Parámetros!$B$8/100)*Parámetros!$B$12)+((Parámetros!$B$6/100)*Parámetros!$B$13+(Parámetros!$B$7/100)*Parámetros!$B$14+((100-Parámetros!$B$6-Parámetros!$B$7)/100)*Parámetros!$B$15)+Parámetros!$B$16)-H5*(((1-Parámetros!$B$8/100)*Parámetros!$B$11+(Parámetros!$B$8/100)*Parámetros!$B$12)+((Parámetros!$B$6/100)*Parámetros!$B$13+(Parámetros!$B$7/100)*Parámetros!$B$14+((100-Parámetros!$B$6-Parámetros!$B$7)/100)*Parámetros!$B$15)+Parámetros!$B$16)*0/Parámetros!$B$68)*Parámetros!$B$66/100) | I39: =(C5*Parámetros!$B$67/Parámetros!$B$68+(C5*Parámetros!$B$67-C5*Parámetros!$B$67*6/Parámetros!$B$68)*Parámetros!$B$66/100)+(D5*Parámetros!$B$67/Parámetros!$B$68+(D5*Parámetros!$B$67-D5*Parámetros!$B$67*5/Parámetros!$B$68)*Parámetros!$B$66/100)+(E5*Parámetros!$B$67/Parámetros!$B$68+(E5*Parámetros!$B$67-E5*Parámetros!$B$67*4/Parámetros!$B$68)*Parámetros!$B$66/100)+(F5*(((1-Parámetros!$B$8/100)*Parámetros!$B$11+(Parámetros!$B$8/100)*Parámetros!$B$12)+((Parámetros!$B$6/100)*Parámetros!$B$13+(Parámetros!$B$7/100)*Parámetros!$B$14+((100-Parámetros!$B$6-Parámetros!$B$7)/100)*Parámetros!$B$15)+Parámetros!$B$16)/Parámetros!$B$68+(F5*(((1-Parámetros!$B$8/100)*Parámetros!$B$11+(Parámetros!$B$8/100)*Parámetros!$B$12)+((Parámetros!$B$6/100)*Parámetros!$B$13+(Parámetros!$B$7/100)*Parámetros!$B$14+((100-Parámetros!$B$6-Parámetros!$B$7)/100)*Parámetros!$B$15)+Parámetros!$B$16)-F5*(((1-Parámetros!$B$8/100)*Parámetros!$B$11+(Parámetros!$B$8/100)*Parámetros!$B$12)+((Parámetros!$B$6/100)*Parámetros!$B$13+(Parámetros!$B$7/100)*Parámetros!$B$14+((100-Parámetros!$B$6-Parámetros!$B$7)/100)*Parámetros!$B$15)+Parámetros!$B$16)*3/Parámetros!$B$68)*Parámetros!$B$66/100)+(G5*(((1-Parámetros!$B$8/100)*Parámetros!$B$11+(Parámetros!$B$8/100)*Parámetros!$B$12)+((Parámetros!$B$6/100)*Parámetros!$B$13+(Parámetros!$B$7/100)*Parámetros!$B$14+((100-Parámetros!$B$6-Parámetros!$B$7)/100)*Parámetros!$B$15)+Parámetros!$B$16)/Parámetros!$B$68+(G5*(((1-Parámetros!$B$8/100)*Parámetros!$B$11+(Parámetros!$B$8/100)*Parámetros!$B$12)+((Parámetros!$B$6/100)*Parámetros!$B$13+(Parámetros!$B$7/100)*Parámetros!$B$14+((100-Parámetros!$B$6-Parámetros!$B$7)/100)*Parámetros!$B$15)+Parámetros!$B$16)-G5*(((1-Parámetros!$B$8/100)*Parámetros!$B$11+(Parámetros!$B$8/100)*Parámetros!$B$12)+((Parámetros!$B$6/100)*Parámetros!$B$13+(Parámetros!$B$7/100)*Parámetros!$B$14+((100-Parámetros!$B$6-Parámetros!$B$7)/100)*Parámetros!$B$15)+Parámetros!$B$16)*2/Parámetros!$B$68)*Parámetros!$B$66/100)+(H5*(((1-Parámetros!$B$8/100)*Parámetros!$B$11+(Parámetros!$B$8/100)*Parámetros!$B$12)+((Parámetros!$B$6/100)*Parámetros!$B$13+(Parámetros!$B$7/100)*Parámetros!$B$14+((100-Parámetros!$B$6-Parámetros!$B$7)/100)*Parámetros!$B$15)+Parámetros!$B$16)/Parámetros!$B$68+(H5*(((1-Parámetros!$B$8/100)*Parámetros!$B$11+(Parámetros!$B$8/100)*Parámetros!$B$12)+((Parámetros!$B$6/100)*Parámetros!$B$13+(Parámetros!$B$7/100)*Parámetros!$B$14+((100-Parámetros!$B$6-Parámetros!$B$7)/100)*Parámetros!$B$15)+Parámetros!$B$16)-H5*(((1-Parámetros!$B$8/100)*Parámetros!$B$11+(Parámetros!$B$8/100)*Parámetros!$B$12)+((Parámetros!$B$6/100)*Parámetros!$B$13+(Parámetros!$B$7/100)*Parámetros!$B$14+((100-Parámetros!$B$6-Parámetros!$B$7)/100)*Parámetros!$B$15)+Parámetros!$B$16)*1/Parámetros!$B$68)*Parámetros!$B$66/100)+(I5*(((1-Parámetros!$B$8/100)*Parámetros!$B$11+(Parámetros!$B$8/100)*Parámetros!$B$12)+((Parámetros!$B$6/100)*Parámetros!$B$13+(Parámetros!$B$7/100)*Parámetros!$B$14+((100-Parámetros!$B$6-Parámetros!$B$7)/100)*Parámetros!$B$15)+Parámetros!$B$16)/Parámetros!$B$68+(I5*(((1-Parámetros!$B$8/100)*Parámetros!$B$11+(Parámetros!$B$8/100)*Parámetros!$B$12)+((Parámetros!$B$6/100)*Parámetros!$B$13+(Parámetros!$B$7/100)*Parámetros!$B$14+((100-Parámetros!$B$6-Parámetros!$B$7)/100)*Parámetros!$B$15)+Parámetros!$B$16)-I5*(((1-Parámetros!$B$8/100)*Parámetros!$B$11+(Parámetros!$B$8/100)*Parámetros!$B$12)+((Parámetros!$B$6/100)*Parámetros!$B$13+(Parámetros!$B$7/100)*Parámetros!$B$14+((100-Parámetros!$B$6-Parámetros!$B$7)/100)*Parámetros!$B$15)+Parámetros!$B$16)*0/Parámetros!$B$68)*Parámetros!$B$66/100) | J39: =(C5*Parámetros!$B$67/Parámetros!$B$68+(C5*Parámetros!$B$67-C5*Parámetros!$B$67*7/Parámetros!$B$68)*Parámetros!$B$66/100)+(D5*Parámetros!$B$67/Parámetros!$B$68+(D5*Parámetros!$B$67-D5*Parámetros!$B$67*6/Parámetros!$B$68)*Parámetros!$B$66/100)+(E5*Parámetros!$B$67/Parámetros!$B$68+(E5*Parámetros!$B$67-E5*Parámetros!$B$67*5/Parámetros!$B$68)*Parámetros!$B$66/100)+(F5*(((1-Parámetros!$B$8/100)*Parámetros!$B$11+(Parámetros!$B$8/100)*Parámetros!$B$12)+((Parámetros!$B$6/100)*Parámetros!$B$13+(Parámetros!$B$7/100)*Parámetros!$B$14+((100-Parámetros!$B$6-Parámetros!$B$7)/100)*Parámetros!$B$15)+Parámetros!$B$16)/Parámetros!$B$68+(F5*(((1-Parámetros!$B$8/100)*Parámetros!$B$11+(Parámetros!$B$8/100)*Parámetros!$B$12)+((Parámetros!$B$6/100)*Parámetros!$B$13+(Parámetros!$B$7/100)*Parámetros!$B$14+((100-Parámetros!$B$6-Parámetros!$B$7)/100)*Parámetros!$B$15)+Parámetros!$B$16)-F5*(((1-Parámetros!$B$8/100)*Parámetros!$B$11+(Parámetros!$B$8/100)*Parámetros!$B$12)+((Parámetros!$B$6/100)*Parámetros!$B$13+(Parámetros!$B$7/100)*Parámetros!$B$14+((100-Parámetros!$B$6-Parámetros!$B$7)/100)*Parámetros!$B$15)+Parámetros!$B$16)*4/Parámetros!$B$68)*Parámetros!$B$66/100)+(G5*(((1-Parámetros!$B$8/100)*Parámetros!$B$11+(Parámetros!$B$8/100)*Parámetros!$B$12)+((Parámetros!$B$6/100)*Parámetros!$B$13+(Parámetros!$B$7/100)*Parámetros!$B$14+((100-Parámetros!$B$6-Parámetros!$B$7)/100)*Parámetros!$B$15)+Parámetros!$B$16)/Parámetros!$B$68+(G5*(((1-Parámetros!$B$8/100)*Parámetros!$B$11+(Parámetros!$B$8/100)*Parámetros!$B$12)+((Parámetros!$B$6/100)*Parámetros!$B$13+(Parámetros!$B$7/100)*Parámetros!$B$14+((100-Parámetros!$B$6-Parámetros!$B$7)/100)*Parámetros!$B$15)+Parámetros!$B$16)-G5*(((1-Parámetros!$B$8/100)*Parámetros!$B$11+(Parámetros!$B$8/100)*Parámetros!$B$12)+((Parámetros!$B$6/100)*Parámetros!$B$13+(Parámetros!$B$7/100)*Parámetros!$B$14+((100-Parámetros!$B$6-Parámetros!$B$7)/100)*Parámetros!$B$15)+Parámetros!$B$16)*3/Parámetros!$B$68)*Parámetros!$B$66/100)+(H5*(((1-Parámetros!$B$8/100)*Parámetros!$B$11+(Parámetros!$B$8/100)*Parámetros!$B$12)+((Parámetros!$B$6/100)*Parámetros!$B$13+(Parámetros!$B$7/100)*Parámetros!$B$14+((100-Parámetros!$B$6-Parámetros!$B$7)/100)*Parámetros!$B$15)+Parámetros!$B$16)/Parámetros!$B$68+(H5*(((1-Parámetros!$B$8/100)*Parámetros!$B$11+(Parámetros!$B$8/100)*Parámetros!$B$12)+((Parámetros!$B$6/100)*Parámetros!$B$13+(Parámetros!$B$7/100)*Parámetros!$B$14+((100-Parámetros!$B$6-Parámetros!$B$7)/100)*Parámetros!$B$15)+Parámetros!$B$16)-H5*(((1-Parámetros!$B$8/100)*Parámetros!$B$11+(Parámetros!$B$8/100)*Parámetros!$B$12)+((Parámetros!$B$6/100)*Parámetros!$B$13+(Parámetros!$B$7/100)*Parámetros!$B$14+((100-Parámetros!$B$6-Parámetros!$B$7)/100)*Parámetros!$B$15)+Parámetros!$B$16)*2/Parámetros!$B$68)*Parámetros!$B$66/100)+(I5*(((1-Parámetros!$B$8/100)*Parámetros!$B$11+(Parámetros!$B$8/100)*Parámetros!$B$12)+((Parámetros!$B$6/100)*Parámetros!$B$13+(Parámetros!$B$7/100)*Parámetros!$B$14+((100-Parámetros!$B$6-Parámetros!$B$7)/100)*Parámetros!$B$15)+Parámetros!$B$16)/Parámetros!$B$68+(I5*(((1-Parámetros!$B$8/100)*Parámetros!$B$11+(Parámetros!$B$8/100)*Parámetros!$B$12)+((Parámetros!$B$6/100)*Parámetros!$B$13+(Parámetros!$B$7/100)*Parámetros!$B$14+((100-Parámetros!$B$6-Parámetros!$B$7)/100)*Parámetros!$B$15)+Parámetros!$B$16)-I5*(((1-Parámetros!$B$8/100)*Parámetros!$B$11+(Parámetros!$B$8/100)*Parámetros!$B$12)+((Parámetros!$B$6/100)*Parámetros!$B$13+(Parámetros!$B$7/100)*Parámetros!$B$14+((100-Parámetros!$B$6-Parámetros!$B$7)/100)*Parámetros!$B$15)+Parámetros!$B$16)*1/Parámetros!$B$68)*Parámetros!$B$66/100)+(J5*(((1-Parámetros!$B$8/100)*Parámetros!$B$11+(Parámetros!$B$8/100)*Parámetros!$B$12)+((Parámetros!$B$6/100)*Parámetros!$B$13+(Parámetros!$B$7/100)*Parámetros!$B$14+((100-Parámetros!$B$6-Parámetros!$B$7)/100)*Parámetros!$B$15)+Parámetros!$B$16)/Parámetros!$B$68+(J5*(((1-Parámetros!$B$8/100)*Parámetros!$B$11+(Parámetros!$B$8/100)*Parámetros!$B$12)+((Parámetros!$B$6/100)*Parámetros!$B$13+(Parámetros!$B$7/100)*Parámetros!$B$14+((100-Parámetros!$B$6-Parámetros!$B$7)/100)*Parámetros!$B$15)+Parámetros!$B$16)-J5*(((1-Parámetros!$B$8/100)*Parámetros!$B$11+(Parámetros!$B$8/100)*Parámetros!$B$12)+((Parámetros!$B$6/100)*Parámetros!$B$13+(Parámetros!$B$7/100)*Parámetros!$B$14+((100-Parámetros!$B$6-Parámetros!$B$7)/100)*Parámetros!$B$15)+Parámetros!$B$16)*0/Parámetros!$B$68)*Parámetros!$B$66/100) | K39: =(C5*Parámetros!$B$67/Parámetros!$B$68+(C5*Parámetros!$B$67-C5*Parámetros!$B$67*8/Parámetros!$B$68)*Parámetros!$B$66/100)+(D5*Parámetros!$B$67/Parámetros!$B$68+(D5*Parámetros!$B$67-D5*Parámetros!$B$67*7/Parámetros!$B$68)*Parámetros!$B$66/100)+(E5*Parámetros!$B$67/Parámetros!$B$68+(E5*Parámetros!$B$67-E5*Parámetros!$B$67*6/Parámetros!$B$68)*Parámetros!$B$66/100)+(F5*(((1-Parámetros!$B$8/100)*Parámetros!$B$11+(Parámetros!$B$8/100)*Parámetros!$B$12)+((Parámetros!$B$6/100)*Parámetros!$B$13+(Parámetros!$B$7/100)*Parámetros!$B$14+((100-Parámetros!$B$6-Parámetros!$B$7)/100)*Parámetros!$B$15)+Parámetros!$B$16)/Parámetros!$B$68+(F5*(((1-Parámetros!$B$8/100)*Parámetros!$B$11+(Parámetros!$B$8/100)*Parámetros!$B$12)+((Parámetros!$B$6/100)*Parámetros!$B$13+(Parámetros!$B$7/100)*Parámetros!$B$14+((100-Parámetros!$B$6-Parámetros!$B$7)/100)*Parámetros!$B$15)+Parámetros!$B$16)-F5*(((1-Parámetros!$B$8/100)*Parámetros!$B$11+(Parámetros!$B$8/100)*Parámetros!$B$12)+((Parámetros!$B$6/100)*Parámetros!$B$13+(Parámetros!$B$7/100)*Parámetros!$B$14+((100-Parámetros!$B$6-Parámetros!$B$7)/100)*Parámetros!$B$15)+Parámetros!$B$16)*5/Parámetros!$B$68)*Parámetros!$B$66/100)+(G5*(((1-Parámetros!$B$8/100)*Parámetros!$B$11+(Parámetros!$B$8/100)*Parámetros!$B$12)+((Parámetros!$B$6/100)*Parámetros!$B$13+(Parámetros!$B$7/100)*Parámetros!$B$14+((100-Parámetros!$B$6-Parámetros!$B$7)/100)*Parámetros!$B$15)+Parámetros!$B$16)/Parámetros!$B$68+(G5*(((1-Parámetros!$B$8/100)*Parámetros!$B$11+(Parámetros!$B$8/100)*Parámetros!$B$12)+((Parámetros!$B$6/100)*Parámetros!$B$13+(Parámetros!$B$7/100)*Parámetros!$B$14+((100-Parámetros!$B$6-Parámetros!$B$7)/100)*Parámetros!$B$15)+Parámetros!$B$16)-G5*(((1-Parámetros!$B$8/100)*Parámetros!$B$11+(Parámetros!$B$8/100)*Parámetros!$B$12)+((Parámetros!$B$6/100)*Parámetros!$B$13+(Parámetros!$B$7/100)*Parámetros!$B$14+((100-Parámetros!$B$6-Parámetros!$B$7)/100)*Parámetros!$B$15)+Parámetros!$B$16)*4/Parámetros!$B$68)*Parámetros!$B$66/100)+(H5*(((1-Parámetros!$B$8/100)*Parámetros!$B$11+(Parámetros!$B$8/100)*Parámetros!$B$12)+((Parámetros!$B$6/100)*Parámetros!$B$13+(Parámetros!$B$7/100)*Parámetros!$B$14+((100-Parámetros!$B$6-Parámetros!$B$7)/100)*Parámetros!$B$15)+Parámetros!$B$16)/Parámetros!$B$68+(H5*(((1-Parámetros!$B$8/100)*Parámetros!$B$11+(Parámetros!$B$8/100)*Parámetros!$B$12)+((Parámetros!$B$6/100)*Parámetros!$B$13+(Parámetros!$B$7/100)*Parámetros!$B$14+((100-Parámetros!$B$6-Parámetros!$B$7)/100)*Parámetros!$B$15)+Parámetros!$B$16)-H5*(((1-Parámetros!$B$8/100)*Parámetros!$B$11+(Parámetros!$B$8/100)*Parámetros!$B$12)+((Parámetros!$B$6/100)*Parámetros!$B$13+(Parámetros!$B$7/100)*Parámetros!$B$14+((100-Parámetros!$B$6-Parámetros!$B$7)/100)*Parámetros!$B$15)+Parámetros!$B$16)*3/Parámetros!$B$68)*Parámetros!$B$66/100)+(I5*(((1-Parámetros!$B$8/100)*Parámetros!$B$11+(Parámetros!$B$8/100)*Parámetros!$B$12)+((Parámetros!$B$6/100)*Parámetros!$B$13+(Parámetros!$B$7/100)*Parámetros!$B$14+((100-Parámetros!$B$6-Parámetros!$B$7)/100)*Parámetros!$B$15)+Parámetros!$B$16)/Parámetros!$B$68+(I5*(((1-Parámetros!$B$8/100)*Parámetros!$B$11+(Parámetros!$B$8/100)*Parámetros!$B$12)+((Parámetros!$B$6/100)*Parámetros!$B$13+(Parámetros!$B$7/100)*Parámetros!$B$14+((100-Parámetros!$B$6-Parámetros!$B$7)/100)*Parámetros!$B$15)+Parámetros!$B$16)-I5*(((1-Parámetros!$B$8/100)*Parámetros!$B$11+(Parámetros!$B$8/100)*Parámetros!$B$12)+((Parámetros!$B$6/100)*Parámetros!$B$13+(Parámetros!$B$7/100)*Parámetros!$B$14+((100-Parámetros!$B$6-Parámetros!$B$7)/100)*Parámetros!$B$15)+Parámetros!$B$16)*2/Parámetros!$B$68)*Parámetros!$B$66/100)+(J5*(((1-Parámetros!$B$8/100)*Parámetros!$B$11+(Parámetros!$B$8/100)*Parámetros!$B$12)+((Parámetros!$B$6/100)*Parámetros!$B$13+(Parámetros!$B$7/100)*Parámetros!$B$14+((100-Parámetros!$B$6-Parámetros!$B$7)/100)*Parámetros!$B$15)+Parámetros!$B$16)/Parámetros!$B$68+(J5*(((1-Parámetros!$B$8/100)*Parámetros!$B$11+(Parámetros!$B$8/100)*Parámetros!$B$12)+((Parámetros!$B$6/100)*Parámetros!$B$13+(Parámetros!$B$7/100)*Parámetros!$B$14+((100-Parámetros!$B$6-Parámetros!$B$7)/100)*Parámetros!$B$15)+Parámetros!$B$16)-J5*(((1-Parámetros!$B$8/100)*Parámetros!$B$11+(Parámetros!$B$8/100)*Parámetros!$B$12)+((Parámetros!$B$6/100)*Parámetros!$B$13+(Parámetros!$B$7/100)*Parámetros!$B$14+((100-Parámetros!$B$6-Parámetros!$B$7)/100)*Parámetros!$B$15)+Parámetros!$B$16)*1/Parámetros!$B$68)*Parámetros!$B$66/100)+(K5*(((1-Parámetros!$B$8/100)*Parámetros!$B$11+(Parámetros!$B$8/100)*Parámetros!$B$12)+((Parámetros!$B$6/100)*Parámetros!$B$13+(Parámetros!$B$7/100)*Parámetros!$B$14+((100-Parámetros!$B$6-Parámetros!$B$7)/100)*Parámetros!$B$15)+Parámetros!$B$16)/Parámetros!$B$68+(K5*(((1-Parámetros!$B$8/100)*Parámetros!$B$11+(Parámetros!$B$8/100)*Parámetros!$B$12)+((Parámetros!$B$6/100)*Parámetros!$B$13+(Parámetros!$B$7/100)*Parámetros!$B$14+((100-Parámetros!$B$6-Parámetros!$B$7)/100)*Parámetros!$B$15)+Parámetros!$B$16)-K5*(((1-Parámetros!$B$8/100)*Parámetros!$B$11+(Parámetros!$B$8/100)*Parámetros!$B$12)+((Parámetros!$B$6/100)*Parámetros!$B$13+(Parámetros!$B$7/100)*Parámetros!$B$14+((100-Parámetros!$B$6-Parámetros!$B$7)/100)*Parámetros!$B$15)+Parámetros!$B$16)*0/Parámetros!$B$68)*Parámetros!$B$66/100) | L39: =(C5*Parámetros!$B$67/Parámetros!$B$68+(C5*Parámetros!$B$67-C5*Parámetros!$B$67*9/Parámetros!$B$68)*Parámetros!$B$66/100)+(D5*Parámetros!$B$67/Parámetros!$B$68+(D5*Parámetros!$B$67-D5*Parámetros!$B$67*8/Parámetros!$B$68)*Parámetros!$B$66/100)+(E5*Parámetros!$B$67/Parámetros!$B$68+(E5*Parámetros!$B$67-E5*Parámetros!$B$67*7/Parámetros!$B$68)*Parámetros!$B$66/100)+(F5*(((1-Parámetros!$B$8/100)*Parámetros!$B$11+(Parámetros!$B$8/100)*Parámetros!$B$12)+((Parámetros!$B$6/100)*Parámetros!$B$13+(Parámetros!$B$7/100)*Parámetros!$B$14+((100-Parámetros!$B$6-Parámetros!$B$7)/100)*Parámetros!$B$15)+Parámetros!$B$16)/Parámetros!$B$68+(F5*(((1-Parámetros!$B$8/100)*Parámetros!$B$11+(Parámetros!$B$8/100)*Parámetros!$B$12)+((Parámetros!$B$6/100)*Parámetros!$B$13+(Parámetros!$B$7/100)*Parámetros!$B$14+((100-Parámetros!$B$6-Parámetros!$B$7)/100)*Parámetros!$B$15)+Parámetros!$B$16)-F5*(((1-Parámetros!$B$8/100)*Parámetros!$B$11+(Parámetros!$B$8/100)*Parámetros!$B$12)+((Parámetros!$B$6/100)*Parámetros!$B$13+(Parámetros!$B$7/100)*Parámetros!$B$14+((100-Parámetros!$B$6-Parámetros!$B$7)/100)*Parámetros!$B$15)+Parámetros!$B$16)*6/Parámetros!$B$68)*Parámetros!$B$66/100)+(G5*(((1-Parámetros!$B$8/100)*Parámetros!$B$11+(Parámetros!$B$8/100)*Parámetros!$B$12)+((Parámetros!$B$6/100)*Parámetros!$B$13+(Parámetros!$B$7/100)*Parámetros!$B$14+((100-Parámetros!$B$6-Parámetros!$B$7)/100)*Parámetros!$B$15)+Parámetros!$B$16)/Parámetros!$B$68+(G5*(((1-Parámetros!$B$8/100)*Parámetros!$B$11+(Parámetros!$B$8/100)*Parámetros!$B$12)+((Parámetros!$B$6/100)*Parámetros!$B$13+(Parámetros!$B$7/100)*Parámetros!$B$14+((100-Parámetros!$B$6-Parámetros!$B$7)/100)*Parámetros!$B$15)+Parámetros!$B$16)-G5*(((1-Parámetros!$B$8/100)*Parámetros!$B$11+(Parámetros!$B$8/100)*Parámetros!$B$12)+((Parámetros!$B$6/100)*Parámetros!$B$13+(Parámetros!$B$7/100)*Parámetros!$B$14+((100-Parámetros!$B$6-Parámetros!$B$7)/100)*Parámetros!$B$15)+Parámetros!$B$16)*5/Parámetros!$B$68)*Parámetros!$B$66/100)+(H5*(((1-Parámetros!$B$8/100)*Parámetros!$B$11+(Parámetros!$B$8/100)*Parámetros!$B$12)+((Parámetros!$B$6/100)*Parámetros!$B$13+(Parámetros!$B$7/100)*Parámetros!$B$14+((100-Parámetros!$B$6-Parámetros!$B$7)/100)*Parámetros!$B$15)+Parámetros!$B$16)/Parámetros!$B$68+(H5*(((1-Parámetros!$B$8/100)*Parámetros!$B$11+(Parámetros!$B$8/100)*Parámetros!$B$12)+((Parámetros!$B$6/100)*Parámetros!$B$13+(Parámetros!$B$7/100)*Parámetros!$B$14+((100-Parámetros!$B$6-Parámetros!$B$7)/100)*Parámetros!$B$15)+Parámetros!$B$16)-H5*(((1-Parámetros!$B$8/100)*Parámetros!$B$11+(Parámetros!$B$8/100)*Parámetros!$B$12)+((Parámetros!$B$6/100)*Parámetros!$B$13+(Parámetros!$B$7/100)*Parámetros!$B$14+((100-Parámetros!$B$6-Parámetros!$B$7)/100)*Parámetros!$B$15)+Parámetros!$B$16)*4/Parámetros!$B$68)*Parámetros!$B$66/100)+(I5*(((1-Parámetros!$B$8/100)*Parámetros!$B$11+(Parámetros!$B$8/100)*Parámetros!$B$12)+((Parámetros!$B$6/100)*Parámetros!$B$13+(Parámetros!$B$7/100)*Parámetros!$B$14+((100-Parámetros!$B$6-Parámetros!$B$7)/100)*Parámetros!$B$15)+Parámetros!$B$16)/Parámetros!$B$68+(I5*(((1-Parámetros!$B$8/100)*Parámetros!$B$11+(Parámetros!$B$8/100)*Parámetros!$B$12)+((Parámetros!$B$6/100)*Parámetros!$B$13+(Parámetros!$B$7/100)*Parámetros!$B$14+((100-Parámetros!$B$6-Parámetros!$B$7)/100)*Parámetros!$B$15)+Parámetros!$B$16)-I5*(((1-Parámetros!$B$8/100)*Parámetros!$B$11+(Parámetros!$B$8/100)*Parámetros!$B$12)+((Parámetros!$B$6/100)*Parámetros!$B$13+(Parámetros!$B$7/100)*Parámetros!$B$14+((100-Parámetros!$B$6-Parámetros!$B$7)/100)*Parámetros!$B$15)+Parámetros!$B$16)*3/Parámetros!$B$68)*Parámetros!$B$66/100)+(J5*(((1-Parámetros!$B$8/100)*Parámetros!$B$11+(Parámetros!$B$8/100)*Parámetros!$B$12)+((Parámetros!$B$6/100)*Parámetros!$B$13+(Parámetros!$B$7/100)*Parámetros!$B$14+((100-Parámetros!$B$6-Parámetros!$B$7)/100)*Parámetros!$B$15)+Parámetros!$B$16)/Parámetros!$B$68+(J5*(((1-Parámetros!$B$8/100)*Parámetros!$B$11+(Parámetros!$B$8/100)*Parámetros!$B$12)+((Parámetros!$B$6/100)*Parámetros!$B$13+(Parámetros!$B$7/100)*Parámetros!$B$14+((100-Parámetros!$B$6-Parámetros!$B$7)/100)*Parámetros!$B$15)+Parámetros!$B$16)-J5*(((1-Parámetros!$B$8/100)*Parámetros!$B$11+(Parámetros!$B$8/100)*Parámetros!$B$12)+((Parámetros!$B$6/100)*Parámetros!$B$13+(Parámetros!$B$7/100)*Parámetros!$B$14+((100-Parámetros!$B$6-Parámetros!$B$7)/100)*Parámetros!$B$15)+Parámetros!$B$16)*2/Parámetros!$B$68)*Parámetros!$B$66/100)+(K5*(((1-Parámetros!$B$8/100)*Parámetros!$B$11+(Parámetros!$B$8/100)*Parámetros!$B$12)+((Parámetros!$B$6/100)*Parámetros!$B$13+(Parámetros!$B$7/100)*Parámetros!$B$14+((100-Parámetros!$B$6-Parámetros!$B$7)/100)*Parámetros!$B$15)+Parámetros!$B$16)/Parámetros!$B$68+(K5*(((1-Parámetros!$B$8/100)*Parámetros!$B$11+(Parámetros!$B$8/100)*Parámetros!$B$12)+((Parámetros!$B$6/100)*Parámetros!$B$13+(Parámetros!$B$7/100)*Parámetros!$B$14+((100-Parámetros!$B$6-Parámetros!$B$7)/100)*Parámetros!$B$15)+Parámetros!$B$16)-K5*(((1-Parámetros!$B$8/100)*Parámetros!$B$11+(Parámetros!$B$8/100)*Parámetros!$B$12)+((Parámetros!$B$6/100)*Parámetros!$B$13+(Parámetros!$B$7/100)*Parámetros!$B$14+((100-Parámetros!$B$6-Parámetros!$B$7)/100)*Parámetros!$B$15)+Parámetros!$B$16)*1/Parámetros!$B$68)*Parámetros!$B$66/100)+(L5*(((1-Parámetros!$B$8/100)*Parámetros!$B$11+(Parámetros!$B$8/100)*Parámetros!$B$12)+((Parámetros!$B$6/100)*Parámetros!$B$13+(Parámetros!$B$7/100)*Parámetros!$B$14+((100-Parámetros!$B$6-Parámetros!$B$7)/100)*Parámetros!$B$15)+Parámetros!$B$16)/Parámetros!$B$68+(L5*(((1-Parámetros!$B$8/100)*Parámetros!$B$11+(Parámetros!$B$8/100)*Parámetros!$B$12)+((Parámetros!$B$6/100)*Parámetros!$B$13+(Parámetros!$B$7/100)*Parámetros!$B$14+((100-Parámetros!$B$6-Parámetros!$B$7)/100)*Parámetros!$B$15)+Parámetros!$B$16)-L5*(((1-Parámetros!$B$8/100)*Parámetros!$B$11+(Parámetros!$B$8/100)*Parámetros!$B$12)+((Parámetros!$B$6/100)*Parámetros!$B$13+(Parámetros!$B$7/100)*Parámetros!$B$14+((100-Parámetros!$B$6-Parámetros!$B$7)/100)*Parámetros!$B$15)+Parámetros!$B$16)*0/Parámetros!$B$68)*Parámetros!$B$66/100)
A40: INGRESOS VAD TOTALES | B40: =B38+B39 | C40: =C38+C39 | D40: =D38+D39 | E40: =E38+E39 | F40: =F38+F39 | G40: =G38+G39 | H40: =H38+H39 | I40: =I38+I39 | ... L40: =L38+L39
A42: FLUJO DE CAJA
A43: Flujo de Caja Neto (FCF) | B43: =B35+B40-B22-B14 | C43: =C35+C40-C22-C14 | D43: =D35+D40-D22-D14 | E43: =E35+E40-E22-E14 | F43: =F35+F40-F22-F14 | G43: =G35+G40-G22-G14 | H43: =H35+H40-H22-H14 | I43: =I35+I40-I22-I14 | ... L43: =L35+L40-L22-L14
A44: └ FCF Descontado (al WACC del Proyecto) | B44: =B43/(1+Parámetros!$B$5/100)^0 | C44: =C43/(1+Parámetros!$B$5/100)^1 | D44: =D43/(1+Parámetros!$B$5/100)^2 | E44: =E43/(1+Parámetros!$B$5/100)^3 | F44: =F43/(1+Parámetros!$B$5/100)^4 | G44: =G43/(1+Parámetros!$B$5/100)^5 | H44: =H43/(1+Parámetros!$B$5/100)^6 | I44: =I43/(1+Parámetros!$B$5/100)^7 | J44: =J43/(1+Parámetros!$B$5/100)^8 | K44: =K43/(1+Parámetros!$B$5/100)^9 | L44: =L43/(1+Parámetros!$B$5/100)^10
A45: └ VPN Acumulado | B45: =B44 | C45: =SUM(B44:C44) | D45: =SUM(B44:D44) | E45: =SUM(B44:E44) | F45: =SUM(B44:F44) | G45: =SUM(B44:G44) | H45: =SUM(B44:H44) | I45: =SUM(B44:I44) | J45: =SUM(B44:J44) | K45: =SUM(B44:K44) | L45: =SUM(B44:L44)
