Workbook

Sheet Parámetros
A1: Parámetro | B1: Valor | C1: Unidad
A2: GLOBAL — Proyecto
A3: Total Suministros (Medidores) | B3: 2700000 | C3: unidades
A4: Horizonte de Análisis | B4: 10 | C4: años
A5: WACC del Proyecto | B5: 14.2 | C5: %
A6: Mix Wi-SUN | B6: 20 | C6: %
A7: Mix PLC | B7: 75 | C7: %
A8: Mix Medidores T2/T3 | B8: 2 | C8: %
A9: Rampa Inicial Año 1 | B9: 100000 | C9: unidades
A10: CAPEX — Medidores e Instalación
A11: Costo Medidor T1 | B11: 60 | C11: USD/unidad
A12: Costo Medidor T2/T3 | B12: 100 | C12: USD/unidad
A13: Módulo Comunicación Wi-SUN | B13: 15 | C13: USD/unidad
A14: Módulo Comunicación PLC | B14: 15 | C14: USD/unidad
A15: Módulo Comunicación P2P/Celular | B15: 15 | C15: USD/unidad
A16: Costo Instalación (MO) | B16: 35 | C16: USD/unidad
A17: Logística por Medidor | B17: 5 | C17: USD/unidad
A18: Concentrador PLC | B18: 700 | C18: USD/nodo
A19: Focal Point Wi-SUN | B19: 700 | C19: USD/nodo
A20: Medidores por Concentrador PLC | B20: 250 | C20: und/nodo
A21: Medidores por Focal Point Wi-SUN | B21: 5000 | C21: und/nodo
A22: CAPEX — Plataforma IT
A23: Costo Integración IT Total | B23: 15000000 | C23: USD
A24: Costo Project Management | B24: 1000000 | C24: USD
A25: Desembolso IT Año 0 | B25: 40 | C25: %
A26: Desembolso IT Año 1 | B26: 30 | C26: %
A27: Desembolso IT Año 2 | B27: 20 | C27: %
A28: Desembolso IT Año 3 | B28: 10 | C28: %
A29: OPEX
A30: Mantenimiento IT Anual | B30: 500000 | C30: USD/año
A31: Licencias SaaS Anual | B31: 200000 | C31: USD/año
A32: Administración y Soporte | B32: 500000 | C32: USD/año
A33: Telecomunicaciones P2P (mensual/medidor) | B33: 0.52 | C33: USD/med/mes
A34: Cloud Mensual (base fija) | B34: 5000 | C34: USD/mes
A35: BENEFICIOS — Operacionales
A36: Volumen Lecturas Manuales Anuales | B36: 32400000 | C36: lecturas
A37: Costo Unitario por Lectura | B37: 0.25 | C37: USD/lectura
A38: Cortes Anuales (manual) | B38: 318250 | C38: eventos
A39: Reposiciones Anuales (manual) | B39: 152000 | C39: eventos
A40: Costo Despacho Cuadrilla | B40: 14.6 | C40: USD/visita
...

Sheet Flujo de Fondos
A1: Concepto / Fórmula | B1: Año 0 | C1: Año 1 | D1: Año 2 | E1: Año 3 | F1: Año 4 | G1: Año 5 | H1: Año 6 | I1: Año 7 | J1: Año 8 | K1: Año 9 | L1: Año 10
A2: DESPLIEGUE DE MEDIDORES
A3: └ SM Instalados en el Año | B3: 0 | C3: =Parámetros!$B$9 | D3: =(Parámetros!$B$3-Parámetros!$B$9)/(Parámetros!$B$4-1) | E3: =(Parámetros!$B$3-Parámetros!$B$9)/(Parámetros!$B$4-1) | F3: =(Parámetros!$B$3-Parámetros!$B$9)/(Parámetros!$B$4-1) | G3: =(Parámetros!$B$3-Parámetros!$B$9)/(Parámetros!$B$4-1) | H3: =(Parámetros!$B$3-Parámetros!$B$9)/(Parámetros!$B$4-1) | I3: =(Parámetros!$B$3-Parámetros!$B$9)/(Parámetros!$B$4-1) | J3: =(Parámetros!$B$3-Parámetros!$B$9)/(Parámetros!$B$4-1) | K3: =(Parámetros!$B$3-Parámetros!$B$9)/(Parámetros!$B$4-1) | L3: =(Parámetros!$B$3-Parámetros!$B$9)/(Parámetros!$B$4-1)
A4: └ SM Acumulados (Total Red) | B4: 0 | C4: =SUM(B3:C3) | D4: =SUM(B3:D3) | E4: =SUM(B3:E3) | F4: =SUM(B3:F3) | G4: =SUM(B3:G3) | H4: =SUM(B3:H3) | I4: =SUM(B3:I3) | J4: =SUM(B3:J3) | K4: =SUM(B3:K3) | L4: =SUM(B3:L3)
A5: └ Avance del Despliegue | B5: 0 | C5: =C4/Parámetros!$B$3 | D5: =D4/Parámetros!$B$3 | E5: =E4/Parámetros!$B$3 | F5: =F4/Parámetros!$B$3 | G5: =G4/Parámetros!$B$3 | H5: =H4/Parámetros!$B$3 | I5: =I4/Parámetros!$B$3 | J5: =J4/Parámetros!$B$3 | ... L5: =L4/Parámetros!$B$3
A7: CAPEX — INVERSIÓN
A8: └ CAPEX IT y PM | B8: =Parámetros!$B$25/100*Parámetros!$B$23+Parámetros!$B$24 | C8: =Parámetros!$B$26/100*Parámetros!$B$23 | D8: =Parámetros!$B$27/100*Parámetros!$B$23 | E8: =Parámetros!$B$28/100*Parámetros!$B$23 | F8: 0 | G8: 0 | H8: 0 | I8: 0 | J8: 0 | K8: 0 | L8: 0
A9: └ CAPEX Hardware (Medidores + Módulos Comms) | B9: 0 | C9: =C3*(((1-Parámetros!$B$8/100)*Parámetros!$B$11+(Parámetros!$B$8/100)*Parámetros!$B$12)+((Parámetros!$B$6/100)*Parámetros!$B$13+(Parámetros!$B$7/100)*Parámetros!$B$14+((100-Parámetros!$B$6-Parámetros!$B$7)/100)*Parámetros!$B$15)) | D9: =D3*(((1-Parámetros!$B$8/100)*Parámetros!$B$11+(Parámetros!$B$8/100)*Parámetros!$B$12)+((Parámetros!$B$6/100)*Parámetros!$B$13+(Parámetros!$B$7/100)*Parámetros!$B$14+((100-Parámetros!$B$6-Parámetros!$B$7)/100)*Parámetros!$B$15)) | E9: =E3*(((1-Parámetros!$B$8/100)*Parámetros!$B$11+(Parámetros!$B$8/100)*Parámetros!$B$12)+((Parámetros!$B$6/100)*Parámetros!$B$13+(Parámetros!$B$7/100)*Parámetros!$B$14+((100-Parámetros!$B$6-Parámetros!$B$7)/100)*Parámetros!$B$15)) | F9: =F3*(((1-Parámetros!$B$8/100)*Parámetros!$B$11+(Parámetros!$B$8/100)*Parámetros!$B$12)+((Parámetros!$B$6/100)*Parámetros!$B$13+(Parámetros!$B$7/100)*Parámetros!$B$14+((100-Parámetros!$B$6-Parámetros!$B$7)/100)*Parámetros!$B$15)) | G9: =G3*(((1-Parámetros!$B$8/100)*Parámetros!$B$11+(Parámetros!$B$8/100)*Parámetros!$B$12)+((Parámetros!$B$6/100)*Parámetros!$B$13+(Parámetros!$B$7/100)*Parámetros!$B$14+((100-Parámetros!$B$6-Parámetros!$B$7)/100)*Parámetros!$B$15)) | H9: =H3*(((1-Parámetros!$B$8/100)*Parámetros!$B$11+(Parámetros!$B$8/100)*Parámetros!$B$12)+((Parámetros!$B$6/100)*Parámetros!$B$13+(Parámetros!$B$7/100)*Parámetros!$B$14+((100-Parámetros!$B$6-Parámetros!$B$7)/100)*Parámetros!$B$15)) | I9: =I3*(((1-Parámetros!$B$8/100)*Parámetros!$B$11+(Parámetros!$B$8/100)*Parámetros!$B$12)+((Parámetros!$B$6/100)*Parámetros!$B$13+(Parámetros!$B$7/100)*Parámetros!$B$14+((100-Parámetros!$B$6-Parámetros!$B$7)/100)*Parámetros!$B$15)) | J9: =J3*(((1-Parámetros!$B$8/100)*Parámetros!$B$11+(Parámetros!$B$8/100)*Parámetros!$B$12)+((Parámetros!$B$6/100)*Parámetros!$B$13+(Parámetros!$B$7/100)*Parámetros!$B$14+((100-Parámetros!$B$6-Parámetros!$B$7)/100)*Parámetros!$B$15)) | ... L9: =L3*(((1-Parámetros!$B$8/100)*Parámetros!$B$11+(Parámetros!$B$8/100)*Parámetros!$B$12)+((Parámetros!$B$6/100)*Parámetros!$B$13+(Parámetros!$B$7/100)*Parámetros!$B$14+((100-Parámetros!$B$6-Parámetros!$B$7)/100)*Parámetros!$B$15))
A10: └ CAPEX Instalación y Logística | B10: 0 | C10: =C3*(Parámetros!$B$16+Parámetros!$B$17) | D10: =D3*(Parámetros!$B$16+Parámetros!$B$17) | E10: =E3*(Parámetros!$B$16+Parámetros!$B$17) | F10: =F3*(Parámetros!$B$16+Parámetros!$B$17) | G10: =G3*(Parámetros!$B$16+Parámetros!$B$17) | H10: =H3*(Parámetros!$B$16+Parámetros!$B$17) | I10: =I3*(Parámetros!$B$16+Parámetros!$B$17) | J10: =J3*(Parámetros!$B$16+Parámetros!$B$17) | ... L10: =L3*(Parámetros!$B$16+Parámetros!$B$17)
A11: └ CAPEX Infraestructura (Nodos de Red) | B11: 0 | C11: =(C3*Parámetros!$B$7/100)/Parámetros!$B$20*Parámetros!$B$18+(C3*Parámetros!$B$6/100)/Parámetros!$B$21*Parámetros!$B$19 | D11: =(D3*Parámetros!$B$7/100)/Parámetros!$B$20*Parámetros!$B$18+(D3*Parámetros!$B$6/100)/Parámetros!$B$21*Parámetros!$B$19 | E11: =(E3*Parámetros!$B$7/100)/Parámetros!$B$20*Parámetros!$B$18+(E3*Parámetros!$B$6/100)/Parámetros!$B$21*Parámetros!$B$19 | F11: =(F3*Parámetros!$B$7/100)/Parámetros!$B$20*Parámetros!$B$18+(F3*Parámetros!$B$6/100)/Parámetros!$B$21*Parámetros!$B$19 | G11: =(G3*Parámetros!$B$7/100)/Parámetros!$B$20*Parámetros!$B$18+(G3*Parámetros!$B$6/100)/Parámetros!$B$21*Parámetros!$B$19 | H11: =(H3*Parámetros!$B$7/100)/Parámetros!$B$20*Parámetros!$B$18+(H3*Parámetros!$B$6/100)/Parámetros!$B$21*Parámetros!$B$19 | I11: =(I3*Parámetros!$B$7/100)/Parámetros!$B$20*Parámetros!$B$18+(I3*Parámetros!$B$6/100)/Parámetros!$B$21*Parámetros!$B$19 | J11: =(J3*Parámetros!$B$7/100)/Parámetros!$B$20*Parámetros!$B$18+(J3*Parámetros!$B$6/100)/Parámetros!$B$21*Parámetros!$B$19 | ... L11: =(L3*Parámetros!$B$7/100)/Parámetros!$B$20*Parámetros!$B$18+(L3*Parámetros!$B$6/100)/Parámetros!$B$21*Parámetros!$B$19
A12: CAPEX TOTAL | B12: =B8+B9+B10+B11 | C12: =C8+C9+C10+C11 | D12: =D8+D9+D10+D11 | E12: =E8+E9+E10+E11 | F12: =F8+F9+F10+F11 | G12: =G8+G9+G10+G11 | H12: =H8+H9+H10+H11 | I12: =I8+I9+I10+I11 | ... L12: =L8+L9+L10+L11
A14: OPEX — COSTOS OPERATIVOS
A15: └ Mantenimiento IT | B15: 0 | C15: =Parámetros!$B$30 | D15: =Parámetros!$B$30 | E15: =Parámetros!$B$30 | F15: =Parámetros!$B$30 | G15: =Parámetros!$B$30 | H15: =Parámetros!$B$30 | I15: =Parámetros!$B$30 | J15: =Parámetros!$B$30 | ... L15: =Parámetros!$B$30
A16: └ Licencias SaaS | B16: 0 | C16: =Parámetros!$B$31 | D16: =Parámetros!$B$31 | E16: =Parámetros!$B$31 | F16: =Parámetros!$B$31 | G16: =Parámetros!$B$31 | H16: =Parámetros!$B$31 | I16: =Parámetros!$B$31 | J16: =Parámetros!$B$31 | ... L16: =Parámetros!$B$31
A17: └ Administración y Soporte (Personal) | B17: 0 | C17: =Parámetros!$B$32 | D17: =Parámetros!$B$32 | E17: =Parámetros!$B$32 | F17: =Parámetros!$B$32 | G17: =Parámetros!$B$32 | H17: =Parámetros!$B$32 | I17: =Parámetros!$B$32 | J17: =Parámetros!$B$32 | ... L17: =Parámetros!$B$32
A18: └ Telecomunicaciones P2P (var. según red activa) | B18: 0 | C18: =C4*((100-Parámetros!$B$6-Parámetros!$B$7)/100)*Parámetros!$B$33*12 | D18: =D4*((100-Parámetros!$B$6-Parámetros!$B$7)/100)*Parámetros!$B$33*12 | E18: =E4*((100-Parámetros!$B$6-Parámetros!$B$7)/100)*Parámetros!$B$33*12 | F18: =F4*((100-Parámetros!$B$6-Parámetros!$B$7)/100)*Parámetros!$B$33*12 | G18: =G4*((100-Parámetros!$B$6-Parámetros!$B$7)/100)*Parámetros!$B$33*12 | H18: =H4*((100-Parámetros!$B$6-Parámetros!$B$7)/100)*Parámetros!$B$33*12 | I18: =I4*((100-Parámetros!$B$6-Parámetros!$B$7)/100)*Parámetros!$B$33*12 | J18: =J4*((100-Parámetros!$B$6-Parámetros!$B$7)/100)*Parámetros!$B$33*12 | ... L18: =L4*((100-Parámetros!$B$6-Parámetros!$B$7)/100)*Parámetros!$B$33*12
A19: └ Cloud (base mensual fija) | B19: 0 | C19: =Parámetros!$B$34*12 | D19: =Parámetros!$B$34*12 | E19: =Parámetros!$B$34*12 | F19: =Parámetros!$B$34*12 | G19: =Parámetros!$B$34*12 | H19: =Parámetros!$B$34*12 | I19: =Parámetros!$B$34*12 | J19: =Parámetros!$B$34*12 | ... L19: =Parámetros!$B$34*12
A20: OPEX TOTAL | B20: =B15+B16+B17+B18+B19 | C20: =C15+C16+C17+C18+C19 | D20: =D15+D16+D17+D18+D19 | E20: =E15+E16+E17+E18+E19 | F20: =F15+F16+F17+F18+F19 | G20: =G15+G16+G17+G18+G19 | H20: =H15+H16+H17+H18+H19 | I20: =I15+I16+I17+I18+I19 | ... L20: =L15+L16+L17+L18+L19
A22: BENEFICIOS — SAVINGS OPERACIONALES Y REGULATORIOS
A23: └ Lecturas Manuales Evitadas | B23: 0 | C23: =Parámetros!$B$36*Parámetros!$B$37*C5 | D23: =Parámetros!$B$36*Parámetros!$B$37*D5 | E23: =Parámetros!$B$36*Parámetros!$B$37*E5 | F23: =Parámetros!$B$36*Parámetros!$B$37*F5 | G23: =Parámetros!$B$36*Parámetros!$B$37*G5 | H23: =Parámetros!$B$36*Parámetros!$B$37*H5 | I23: =Parámetros!$B$36*Parámetros!$B$37*I5 | J23: =Parámetros!$B$36*Parámetros!$B$37*J5 | ... L23: =Parámetros!$B$36*Parámetros!$B$37*L5
A24: └ Cortes y Reposiciones Remotas (cuadrilla evitada) | B24: 0 | C24: =(Parámetros!$B$38+Parámetros!$B$39)*Parámetros!$B$40*C5 | D24: =(Parámetros!$B$38+Parámetros!$B$39)*Parámetros!$B$40*D5 | E24: =(Parámetros!$B$38+Parámetros!$B$39)*Parámetros!$B$40*E5 | F24: =(Parámetros!$B$38+Parámetros!$B$39)*Parámetros!$B$40*F5 | G24: =(Parámetros!$B$38+Parámetros!$B$39)*Parámetros!$B$40*G5 | H24: =(Parámetros!$B$38+Parámetros!$B$39)*Parámetros!$B$40*H5 | I24: =(Parámetros!$B$38+Parámetros!$B$39)*Parámetros!$B$40*I5 | J24: =(Parámetros!$B$38+Parámetros!$B$39)*Parámetros!$B$40*J5 | ... L24: =(Parámetros!$B$38+Parámetros!$B$39)*Parámetros!$B$40*L5
A25: └ Visitas Improductivas + Reiterativas + Calidad Evitadas | B25: 0 | C25: =(Parámetros!$B$41+Parámetros!$B$42+Parámetros!$B$43)*Parámetros!$B$44*C5 | D25: =(Parámetros!$B$41+Parámetros!$B$42+Parámetros!$B$43)*Parámetros!$B$44*D5 | E25: =(Parámetros!$B$41+Parámetros!$B$42+Parámetros!$B$43)*Parámetros!$B$44*E5 | F25: =(Parámetros!$B$41+Parámetros!$B$42+Parámetros!$B$43)*Parámetros!$B$44*F5 | G25: =(Parámetros!$B$41+Parámetros!$B$42+Parámetros!$B$43)*Parámetros!$B$44*G5 | H25: =(Parámetros!$B$41+Parámetros!$B$42+Parámetros!$B$43)*Parámetros!$B$44*H5 | I25: =(Parámetros!$B$41+Parámetros!$B$42+Parámetros!$B$43)*Parámetros!$B$44*I5 | J25: =(Parámetros!$B$41+Parámetros!$B$42+Parámetros!$B$43)*Parámetros!$B$44*J5 | ... L25: =(Parámetros!$B$41+Parámetros!$B$42+Parámetros!$B$43)*Parámetros!$B$44*L5
A26: └ Reducción Multas SAIDI (minutos × penalidad) | B26: 0 | C26: =Parámetros!$B$46*(Parámetros!$B$47/100)*Parámetros!$B$48*C5 | D26: =Parámetros!$B$46*(Parámetros!$B$47/100)*Parámetros!$B$48*D5 | E26: =Parámetros!$B$46*(Parámetros!$B$47/100)*Parámetros!$B$48*E5 | F26: =Parámetros!$B$46*(Parámetros!$B$47/100)*Parámetros!$B$48*F5 | G26: =Parámetros!$B$46*(Parámetros!$B$47/100)*Parámetros!$B$48*G5 | H26: =Parámetros!$B$46*(Parámetros!$B$47/100)*Parámetros!$B$48*H5 | I26: =Parámetros!$B$46*(Parámetros!$B$47/100)*Parámetros!$B$48*I5 | J26: =Parámetros!$B$46*(Parámetros!$B$47/100)*Parámetros!$B$48*J5 | ... L26: =Parámetros!$B$46*(Parámetros!$B$47/100)*Parámetros!$B$48*L5
A27: └ Reducción Multas por Estimación | B27: 0 | C27: =Parámetros!$B$49*C5 | D27: =Parámetros!$B$49*D5 | E27: =Parámetros!$B$49*E5 | F27: =Parámetros!$B$49*F5 | G27: =Parámetros!$B$49*G5 | H27: =Parámetros!$B$49*H5 | I27: =Parámetros!$B$49*I5 | J27: =Parámetros!$B$49*J5 | ... L27: =Parámetros!$B$49*L5
A28: └ Reducción Multas Apartamiento (Calidad de Producto) | B28: 0 | C28: =Parámetros!$B$50*(Parámetros!$B$51/100)*C5 | D28: =Parámetros!$B$50*(Parámetros!$B$51/100)*D5 | E28: =Parámetros!$B$50*(Parámetros!$B$51/100)*E5 | F28: =Parámetros!$B$50*(Parámetros!$B$51/100)*F5 | G28: =Parámetros!$B$50*(Parámetros!$B$51/100)*G5 | H28: =Parámetros!$B$50*(Parámetros!$B$51/100)*H5 | I28: =Parámetros!$B$50*(Parámetros!$B$51/100)*I5 | J28: =Parámetros!$B$50*(Parámetros!$B$51/100)*J5 | ... L28: =Parámetros!$B$50*(Parámetros!$B$51/100)*L5
A29: └ Reducción Multas de Incumplimiento Regulatorio | B29: 0 | C29: =Parámetros!$B$52*(Parámetros!$B$53/100)*C5 | D29: =Parámetros!$B$52*(Parámetros!$B$53/100)*D5 | E29: =Parámetros!$B$52*(Parámetros!$B$53/100)*E5 | F29: =Parámetros!$B$52*(Parámetros!$B$53/100)*F5 | G29: =Parámetros!$B$52*(Parámetros!$B$53/100)*G5 | H29: =Parámetros!$B$52*(Parámetros!$B$53/100)*H5 | I29: =Parámetros!$B$52*(Parámetros!$B$53/100)*I5 | J29: =Parámetros!$B$52*(Parámetros!$B$53/100)*J5 | ... L29: =Parámetros!$B$52*(Parámetros!$B$53/100)*L5
A30: └ Reducción Reclamos y Llamadas Call Center | B30: 0 | C30: =(Parámetros!$B$55+Parámetros!$B$56)*Parámetros!$B$57*C5 | D30: =(Parámetros!$B$55+Parámetros!$B$56)*Parámetros!$B$57*D5 | E30: =(Parámetros!$B$55+Parámetros!$B$56)*Parámetros!$B$57*E5 | F30: =(Parámetros!$B$55+Parámetros!$B$56)*Parámetros!$B$57*F5 | G30: =(Parámetros!$B$55+Parámetros!$B$56)*Parámetros!$B$57*G5 | H30: =(Parámetros!$B$55+Parámetros!$B$56)*Parámetros!$B$57*H5 | I30: =(Parámetros!$B$55+Parámetros!$B$56)*Parámetros!$B$57*I5 | J30: =(Parámetros!$B$55+Parámetros!$B$56)*Parámetros!$B$57*J5 | ... L30: =(Parámetros!$B$55+Parámetros!$B$56)*Parámetros!$B$57*L5
A31: └ Reducción Resarcimientos por Artefactos Quemados | B31: 0 | C31: =Parámetros!$B$58*(Parámetros!$B$59/100)*C5 | D31: =Parámetros!$B$58*(Parámetros!$B$59/100)*D5 | E31: =Parámetros!$B$58*(Parámetros!$B$59/100)*E5 | F31: =Parámetros!$B$58*(Parámetros!$B$59/100)*F5 | G31: =Parámetros!$B$58*(Parámetros!$B$59/100)*G5 | H31: =Parámetros!$B$58*(Parámetros!$B$59/100)*H5 | I31: =Parámetros!$B$58*(Parámetros!$B$59/100)*I5 | J31: =Parámetros!$B$58*(Parámetros!$B$59/100)*J5 | ... L31: =Parámetros!$B$58*(Parámetros!$B$59/100)*L5
A32: └ Recupero Pérdidas No Técnicas / Fraude | B32: 0 | C32: =Parámetros!$B$61*(Parámetros!$B$62/100)*MAX(0,Parámetros!$B$64-Parámetros!$B$63)*C5 | D32: =Parámetros!$B$61*(Parámetros!$B$62/100)*MAX(0,Parámetros!$B$64-Parámetros!$B$63)*D5 | E32: =Parámetros!$B$61*(Parámetros!$B$62/100)*MAX(0,Parámetros!$B$64-Parámetros!$B$63)*E5 | F32: =Parámetros!$B$61*(Parámetros!$B$62/100)*MAX(0,Parámetros!$B$64-Parámetros!$B$63)*F5 | G32: =Parámetros!$B$61*(Parámetros!$B$62/100)*MAX(0,Parámetros!$B$64-Parámetros!$B$63)*G5 | H32: =Parámetros!$B$61*(Parámetros!$B$62/100)*MAX(0,Parámetros!$B$64-Parámetros!$B$63)*H5 | I32: =Parámetros!$B$61*(Parámetros!$B$62/100)*MAX(0,Parámetros!$B$64-Parámetros!$B$63)*I5 | J32: =Parámetros!$B$61*(Parámetros!$B$62/100)*MAX(0,Parámetros!$B$64-Parámetros!$B$63)*J5 | ... L32: =Parámetros!$B$61*(Parámetros!$B$62/100)*MAX(0,Parámetros!$B$64-Parámetros!$B$63)*L5
A33: BENEFICIOS TOTALES | B33: =B23+B24+B25+B26+B27+B28+B29+B30+B31+B32 | C33: =C23+C24+C25+C26+C27+C28+C29+C30+C31+C32 | D33: =D23+D24+D25+D26+D27+D28+D29+D30+D31+D32 | E33: =E23+E24+E25+E26+E27+E28+E29+E30+E31+E32 | F33: =F23+F24+F25+F26+F27+F28+F29+F30+F31+F32 | G33: =G23+G24+G25+G26+G27+G28+G29+G30+G31+G32 | H33: =H23+H24+H25+H26+H27+H28+H29+H30+H31+H32 | I33: =I23+I24+I25+I26+I27+I28+I29+I30+I31+I32 | ... L33: =L23+L24+L25+L26+L27+L28+L29+L30+L31+L32
A35: INGRESOS VAD — RECONOCIMIENTO TARIFARIO ENRE
A36: └ VAD IT (Amortización + Retorno RAB — Plataforma) | B36: =(MAX(0,Parámetros!$B$25/100*Parámetros!$B$23-Parámetros!$B$70)/Parámetros!$B$69+(MAX(0,Parámetros!$B$25/100*Parámetros!$B$23-Parámetros!$B$70)-MAX(0,Parámetros!$B$25/100*Parámetros!$B$23-Parámetros!$B$70)*0/Parámetros!$B$69)*Parámetros!$B$66/100) | C36: =(MAX(0,Parámetros!$B$25/100*Parámetros!$B$23-Parámetros!$B$70)/Parámetros!$B$69+(MAX(0,Parámetros!$B$25/100*Parámetros!$B$23-Parámetros!$B$70)-MAX(0,Parámetros!$B$25/100*Parámetros!$B$23-Parámetros!$B$70)*1/Parámetros!$B$69)*Parámetros!$B$66/100)+(Parámetros!$B$26/100*Parámetros!$B$23/Parámetros!$B$69+(Parámetros!$B$26/100*Parámetros!$B$23-Parámetros!$B$26/100*Parámetros!$B$23*0/Parámetros!$B$69)*Parámetros!$B$66/100) | D36: =(MAX(0,Parámetros!$B$25/100*Parámetros!$B$23-Parámetros!$B$70)/Parámetros!$B$69+(MAX(0,Parámetros!$B$25/100*Parámetros!$B$23-Parámetros!$B$70)-MAX(0,Parámetros!$B$25/100*Parámetros!$B$23-Parámetros!$B$70)*2/Parámetros!$B$69)*Parámetros!$B$66/100)+(Parámetros!$B$26/100*Parámetros!$B$23/Parámetros!$B$69+(Parámetros!$B$26/100*Parámetros!$B$23-Parámetros!$B$26/100*Parámetros!$B$23*1/Parámetros!$B$69)*Parámetros!$B$66/100)+(Parámetros!$B$27/100*Parámetros!$B$23/Parámetros!$B$69+(Parámetros!$B$27/100*Parámetros!$B$23-Parámetros!$B$27/100*Parámetros!$B$23*0/Parámetros!$B$69)*Parámetros!$B$66/100) | E36: =(MAX(0,Parámetros!$B$25/100*Parámetros!$B$23-Parámetros!$B$70)/Parámetros!$B$69+(MAX(0,Parámetros!$B$25/100*Parámetros!$B$23-Parámetros!$B$70)-MAX(0,Parámetros!$B$25/100*Parámetros!$B$23-Parámetros!$B$70)*3/Parámetros!$B$69)*Parámetros!$B$66/100)+(Parámetros!$B$26/100*Parámetros!$B$23/Parámetros!$B$69+(Parámetros!$B$26/100*Parámetros!$B$23-Parámetros!$B$26/100*Parámetros!$B$23*2/Parámetros!$B$69)*Parámetros!$B$66/100)+(Parámetros!$B$27/100*Parámetros!$B$23/Parámetros!$B$69+(Parámetros!$B$27/100*Parámetros!$B$23-Parámetros!$B$27/100*Parámetros!$B$23*1/Parámetros!$B$69)*Parámetros!$B$66/100)+(Parámetros!$B$28/100*Parámetros!$B$23/Parámetros!$B$69+(Parámetros!$B$28/100*Parámetros!$B$23-Parámetros!$B$28/100*Parámetros!$B$23*0/Parámetros!$B$69)*Parámetros!$B$66/100) | F36: =(MAX(0,Parámetros!$B$25/100*Parámetros!$B$23-Parámetros!$B$70)/Parámetros!$B$69+(MAX(0,Parámetros!$B$25/100*Parámetros!$B$23-Parámetros!$B$70)-MAX(0,Parámetros!$B$25/100*Parámetros!$B$23-Parámetros!$B$70)*4/Parámetros!$B$69)*Parámetros!$B$66/100)+(Parámetros!$B$26/100*Parámetros!$B$23/Parámetros!$B$69+(Parámetros!$B$26/100*Parámetros!$B$23-Parámetros!$B$26/100*Parámetros!$B$23*3/Parámetros!$B$69)*Parámetros!$B$66/100)+(Parámetros!$B$27/100*Parámetros!$B$23/Parámetros!$B$69+(Parámetros!$B$27/100*Parámetros!$B$23-Parámetros!$B$27/100*Parámetros!$B$23*2/Parámetros!$B$69)*Parámetros!$B$66/100)+(Parámetros!$B$28/100*Parámetros!$B$23/Parámetros!$B$69+(Parámetros!$B$28/100*Parámetros!$B$23-Parámetros!$B$28/100*Parámetros!$B$23*1/Parámetros!$B$69)*Parámetros!$B$66/100) | G36: =(MAX(0,Parámetros!$B$25/100*Parámetros!$B$23-Parámetros!$B$70)/Parámetros!$B$69+(MAX(0,Parámetros!$B$25/100*Parámetros!$B$23-Parámetros!$B$70)-MAX(0,Parámetros!$B$25/100*Parámetros!$B$23-Parámetros!$B$70)*5/Parámetros!$B$69)*Parámetros!$B$66/100)+(Parámetros!$B$26/100*Parámetros!$B$23/Parámetros!$B$69+(Parámetros!$B$26/100*Parámetros!$B$23-Parámetros!$B$26/100*Parámetros!$B$23*4/Parámetros!$B$69)*Parámetros!$B$66/100)+(Parámetros!$B$27/100*Parámetros!$B$23/Parámetros!$B$69+(Parámetros!$B$27/100*Parámetros!$B$23-Parámetros!$B$27/100*Parámetros!$B$23*3/Parámetros!$B$69)*Parámetros!$B$66/100)+(Parámetros!$B$28/100*Parámetros!$B$23/Parámetros!$B$69+(Parámetros!$B$28/100*Parámetros!$B$23-Parámetros!$B$28/100*Parámetros!$B$23*2/Parámetros!$B$69)*Parámetros!$B$66/100) | H36: =(MAX(0,Parámetros!$B$25/100*Parámetros!$B$23-Parámetros!$B$70)/Parámetros!$B$69+(MAX(0,Parámetros!$B$25/100*Parámetros!$B$23-Parámetros!$B$70)-MAX(0,Parámetros!$B$25/100*Parámetros!$B$23-Parámetros!$B$70)*6/Parámetros!$B$69)*Parámetros!$B$66/100)+(Parámetros!$B$26/100*Parámetros!$B$23/Parámetros!$B$69+(Parámetros!$B$26/100*Parámetros!$B$23-Parámetros!$B$26/100*Parámetros!$B$23*5/Parámetros!$B$69)*Parámetros!$B$66/100)+(Parámetros!$B$27/100*Parámetros!$B$23/Parámetros!$B$69+(Parámetros!$B$27/100*Parámetros!$B$23-Parámetros!$B$27/100*Parámetros!$B$23*4/Parámetros!$B$69)*Parámetros!$B$66/100)+(Parámetros!$B$28/100*Parámetros!$B$23/Parámetros!$B$69+(Parámetros!$B$28/100*Parámetros!$B$23-Parámetros!$B$28/100*Parámetros!$B$23*3/Parámetros!$B$69)*Parámetros!$B$66/100) | I36: =(MAX(0,Parámetros!$B$25/100*Parámetros!$B$23-Parámetros!$B$70)/Parámetros!$B$69+(MAX(0,Parámetros!$B$25/100*Parámetros!$B$23-Parámetros!$B$70)-MAX(0,Parámetros!$B$25/100*Parámetros!$B$23-Parámetros!$B$70)*7/Parámetros!$B$69)*Parámetros!$B$66/100)+(Parámetros!$B$26/100*Parámetros!$B$23/Parámetros!$B$69+(Parámetros!$B$26/100*Parámetros!$B$23-Parámetros!$B$26/100*Parámetros!$B$23*6/Parámetros!$B$69)*Parámetros!$B$66/100)+(Parámetros!$B$27/100*Parámetros!$B$23/Parámetros!$B$69+(Parámetros!$B$27/100*Parámetros!$B$23-Parámetros!$B$27/100*Parámetros!$B$23*5/Parámetros!$B$69)*Parámetros!$B$66/100)+(Parámetros!$B$28/100*Parámetros!$B$23/Parámetros!$B$69+(Parámetros!$B$28/100*Parámetros!$B$23-Parámetros!$B$28/100*Parámetros!$B$23*4/Parámetros!$B$69)*Parámetros!$B$66/100) | J36: =(MAX(0,Parámetros!$B$25/100*Parámetros!$B$23-Parámetros!$B$70)/Parámetros!$B$69+(MAX(0,Parámetros!$B$25/100*Parámetros!$B$23-Parámetros!$B$70)-MAX(0,Parámetros!$B$25/100*Parámetros!$B$23-Parámetros!$B$70)*8/Parámetros!$B$69)*Parámetros!$B$66/100)+(Parámetros!$B$26/100*Parámetros!$B$23/Parámetros!$B$69+(Parámetros!$B$26/100*Parámetros!$B$23-Parámetros!$B$26/100*Parámetros!$B$23*7/Parámetros!$B$69)*Parámetros!$B$66/100)+(Parámetros!$B$27/100*Parámetros!$B$23/Parámetros!$B$69+(Parámetros!$B$27/100*Parámetros!$B$23-Parámetros!$B$27/100*Parámetros!$B$23*6/Parámetros!$B$69)*Parámetros!$B$66/100)+(Parámetros!$B$28/100*Parámetros!$B$23/Parámetros!$B$69+(Parámetros!$B$28/100*Parámetros!$B$23-Parámetros!$B$28/100*Parámetros!$B$23*5/Parámetros!$B$69)*Parámetros!$B$66/100) | K36: =(MAX(0,Parámetros!$B$25/100*Parámetros!$B$23-Parámetros!$B$70)/Parámetros!$B$69+(MAX(0,Parámetros!$B$25/100*Parámetros!$B$23-Parámetros!$B$70)-MAX(0,Parámetros!$B$25/100*Parámetros!$B$23-Parámetros!$B$70)*9/Parámetros!$B$69)*Parámetros!$B$66/100)+(Parámetros!$B$26/100*Parámetros!$B$23/Parámetros!$B$69+(Parámetros!$B$26/100*Parámetros!$B$23-Parámetros!$B$26/100*Parámetros!$B$23*8/Parámetros!$B$69)*Parámetros!$B$66/100)+(Parámetros!$B$27/100*Parámetros!$B$23/Parámetros!$B$69+(Parámetros!$B$27/100*Parámetros!$B$23-Parámetros!$B$27/100*Parámetros!$B$23*7/Parámetros!$B$69)*Parámetros!$B$66/100)+(Parámetros!$B$28/100*Parámetros!$B$23/Parámetros!$B$69+(Parámetros!$B$28/100*Parámetros!$B$23-Parámetros!$B$28/100*Parámetros!$B$23*6/Parámetros!$B$69)*Parámetros!$B$66/100) | L36: =(Parámetros!$B$26/100*Parámetros!$B$23/Parámetros!$B$69+(Parámetros!$B$26/100*Parámetros!$B$23-Parámetros!$B$26/100*Parámetros!$B$23*9/Parámetros!$B$69)*Parámetros!$B$66/100)+(Parámetros!$B$27/100*Parámetros!$B$23/Parámetros!$B$69+(Parámetros!$B$27/100*Parámetros!$B$23-Parámetros!$B$27/100*Parámetros!$B$23*8/Parámetros!$B$69)*Parámetros!$B$66/100)+(Parámetros!$B$28/100*Parámetros!$B$23/Parámetros!$B$69+(Parámetros!$B$28/100*Parámetros!$B$23-Parámetros!$B$28/100*Parámetros!$B$23*7/Parámetros!$B$69)*Parámetros!$B$66/100)
A37: └ VAD Medidores (Amortización + Retorno RAB — por Cohorte) | B37: 0 | C37: =((C3*Parámetros!$B$67)/Parámetros!$B$68+((C3*Parámetros!$B$67)-(C3*Parámetros!$B$67)*0/Parámetros!$B$68)*Parámetros!$B$66/100) | D37: =((C3*Parámetros!$B$67)/Parámetros!$B$68+((C3*Parámetros!$B$67)-(C3*Parámetros!$B$67)*1/Parámetros!$B$68)*Parámetros!$B$66/100)+((D3*Parámetros!$B$67)/Parámetros!$B$68+((D3*Parámetros!$B$67)-(D3*Parámetros!$B$67)*0/Parámetros!$B$68)*Parámetros!$B$66/100) | E37: =((C3*Parámetros!$B$67)/Parámetros!$B$68+((C3*Parámetros!$B$67)-(C3*Parámetros!$B$67)*2/Parámetros!$B$68)*Parámetros!$B$66/100)+((D3*Parámetros!$B$67)/Parámetros!$B$68+((D3*Parámetros!$B$67)-(D3*Parámetros!$B$67)*1/Parámetros!$B$68)*Parámetros!$B$66/100)+((E3*Parámetros!$B$67)/Parámetros!$B$68+((E3*Parámetros!$B$67)-(E3*Parámetros!$B$67)*0/Parámetros!$B$68)*Parámetros!$B$66/100) | F37: =((C3*Parámetros!$B$67)/Parámetros!$B$68+((C3*Parámetros!$B$67)-(C3*Parámetros!$B$67)*3/Parámetros!$B$68)*Parámetros!$B$66/100)+((D3*Parámetros!$B$67)/Parámetros!$B$68+((D3*Parámetros!$B$67)-(D3*Parámetros!$B$67)*2/Parámetros!$B$68)*Parámetros!$B$66/100)+((E3*Parámetros!$B$67)/Parámetros!$B$68+((E3*Parámetros!$B$67)-(E3*Parámetros!$B$67)*1/Parámetros!$B$68)*Parámetros!$B$66/100)+((F3*(((1-Parámetros!$B$8/100)*Parámetros!$B$11+(Parámetros!$B$8/100)*Parámetros!$B$12)+((Parámetros!$B$6/100)*Parámetros!$B$13+(Parámetros!$B$7/100)*Parámetros!$B$14+((100-Parámetros!$B$6-Parámetros!$B$7)/100)*Parámetros!$B$15)+Parámetros!$B$16))/Parámetros!$B$68+((F3*(((1-Parámetros!$B$8/100)*Parámetros!$B$11+(Parámetros!$B$8/100)*Parámetros!$B$12)+((Parámetros!$B$6/100)*Parámetros!$B$13+(Parámetros!$B$7/100)*Parámetros!$B$14+((100-Parámetros!$B$6-Parámetros!$B$7)/100)*Parámetros!$B$15)+Parámetros!$B$16))-(F3*(((1-Parámetros!$B$8/100)*Parámetros!$B$11+(Parámetros!$B$8/100)*Parámetros!$B$12)+((Parámetros!$B$6/100)*Parámetros!$B$13+(Parámetros!$B$7/100)*Parámetros!$B$14+((100-Parámetros!$B$6-Parámetros!$B$7)/100)*Parámetros!$B$15)+Parámetros!$B$16))*0/Parámetros!$B$68)*Parámetros!$B$66/100) | G37: =((C3*Parámetros!$B$67)/Parámetros!$B$68+((C3*Parámetros!$B$67)-(C3*Parámetros!$B$67)*4/Parámetros!$B$68)*Parámetros!$B$66/100)+((D3*Parámetros!$B$67)/Parámetros!$B$68+((D3*Parámetros!$B$67)-(D3*Parámetros!$B$67)*3/Parámetros!$B$68)*Parámetros!$B$66/100)+((E3*Parámetros!$B$67)/Parámetros!$B$68+((E3*Parámetros!$B$67)-(E3*Parámetros!$B$67)*2/Parámetros!$B$68)*Parámetros!$B$66/100)+((F3*(((1-Parámetros!$B$8/100)*Parámetros!$B$11+(Parámetros!$B$8/100)*Parámetros!$B$12)+((Parámetros!$B$6/100)*Parámetros!$B$13+(Parámetros!$B$7/100)*Parámetros!$B$14+((100-Parámetros!$B$6-Parámetros!$B$7)/100)*Parámetros!$B$15)+Parámetros!$B$16))/Parámetros!$B$68+((F3*(((1-Parámetros!$B$8/100)*Parámetros!$B$11+(Parámetros!$B$8/100)*Parámetros!$B$12)+((Parámetros!$B$6/100)*Parámetros!$B$13+(Parámetros!$B$7/100)*Parámetros!$B$14+((100-Parámetros!$B$6-Parámetros!$B$7)/100)*Parámetros!$B$15)+Parámetros!$B$16))-(F3*(((1-Parámetros!$B$8/100)*Parámetros!$B$11+(Parámetros!$B$8/100)*Parámetros!$B$12)+((Parámetros!$B$6/100)*Parámetros!$B$13+(Parámetros!$B$7/100)*Parámetros!$B$14+((100-Parámetros!$B$6-Parámetros!$B$7)/100)*Parámetros!$B$15)+Parámetros!$B$16))*1/Parámetros!$B$68)*Parámetros!$B$66/100)+((G3*(((1-Parámetros!$B$8/100)*Parámetros!$B$11+(Parámetros!$B$8/100)*Parámetros!$B$12)+((Parámetros!$B$6/100)*Parámetros!$B$13+(Parámetros!$B$7/100)*Parámetros!$B$14+((100-Parámetros!$B$6-Parámetros!$B$7)/100)*Parámetros!$B$15)+Parámetros!$B$16))/Parámetros!$B$68+((G3*(((1-Parámetros!$B$8/100)*Parámetros!$B$11+(Parámetros!$B$8/100)*Parámetros!$B$12)+((Parámetros!$B$6/100)*Parámetros!$B$13+(Parámetros!$B$7/100)*Parámetros!$B$14+((100-Parámetros!$B$6-Parámetros!$B$7)/100)*Parámetros!$B$15)+Parámetros!$B$16))-(G3*(((1-Parámetros!$B$8/100)*Parámetros!$B$11+(Parámetros!$B$8/100)*Parámetros!$B$12)+((Parámetros!$B$6/100)*Parámetros!$B$13+(Parámetros!$B$7/100)*Parámetros!$B$14+((100-Parámetros!$B$6-Parámetros!$B$7)/100)*Parámetros!$B$15)+Parámetros!$B$16))*0/Parámetros!$B$68)*Parámetros!$B$66/100) | H37: =((C3*Parámetros!$B$67)/Parámetros!$B$68+((C3*Parámetros!$B$67)-(C3*Parámetros!$B$67)*5/Parámetros!$B$68)*Parámetros!$B$66/100)+((D3*Parámetros!$B$67)/Parámetros!$B$68+((D3*Parámetros!$B$67)-(D3*Parámetros!$B$67)*4/Parámetros!$B$68)*Parámetros!$B$66/100)+((E3*Parámetros!$B$67)/Parámetros!$B$68+((E3*Parámetros!$B$67)-(E3*Parámetros!$B$67)*3/Parámetros!$B$68)*Parámetros!$B$66/100)+((F3*(((1-Parámetros!$B$8/100)*Parámetros!$B$11+(Parámetros!$B$8/100)*Parámetros!$B$12)+((Parámetros!$B$6/100)*Parámetros!$B$13+(Parámetros!$B$7/100)*Parámetros!$B$14+((100-Parámetros!$B$6-Parámetros!$B$7)/100)*Parámetros!$B$15)+Parámetros!$B$16))/Parámetros!$B$68+((F3*(((1-Parámetros!$B$8/100)*Parámetros!$B$11+(Parámetros!$B$8/100)*Parámetros!$B$12)+((Parámetros!$B$6/100)*Parámetros!$B$13+(Parámetros!$B$7/100)*Parámetros!$B$14+((100-Parámetros!$B$6-Parámetros!$B$7)/100)*Parámetros!$B$15)+Parámetros!$B$16))-(F3*(((1-Parámetros!$B$8/100)*Parámetros!$B$11+(Parámetros!$B$8/100)*Parámetros!$B$12)+((Parámetros!$B$6/100)*Parámetros!$B$13+(Parámetros!$B$7/100)*Parámetros!$B$14+((100-Parámetros!$B$6-Parámetros!$B$7)/100)*Parámetros!$B$15)+Parámetros!$B$16))*2/Parámetros!$B$68)*Parámetros!$B$66/100)+((G3*(((1-Parámetros!$B$8/100)*Parámetros!$B$11+(Parámetros!$B$8/100)*Parámetros!$B$12)+((Parámetros!$B$6/100)*Parámetros!$B$13+(Parámetros!$B$7/100)*Parámetros!$B$14+((100-Parámetros!$B$6-Parámetros!$B$7)/100)*Parámetros!$B$15)+Parámetros!$B$16))/Parámetros!$B$68+((G3*(((1-Parámetros!$B$8/100)*Parámetros!$B$11+(Parámetros!$B$8/100)*Parámetros!$B$12)+((Parámetros!$B$6/100)*Parámetros!$B$13+(Parámetros!$B$7/100)*Parámetros!$B$14+((100-Parámetros!$B$6-Parámetros!$B$7)/100)*Parámetros!$B$15)+Parámetros!$B$16))-(G3*(((1-Parámetros!$B$8/100)*Parámetros!$B$11+(Parámetros!$B$8/100)*Parámetros!$B$12)+((Parámetros!$B$6/100)*Parámetros!$B$13+(Parámetros!$B$7/100)*Parámetros!$B$14+((100-Parámetros!$B$6-Parámetros!$B$7)/100)*Parámetros!$B$15)+Parámetros!$B$16))*1/Parámetros!$B$68)*Parámetros!$B$66/100)+((H3*(((1-Parámetros!$B$8/100)*Parámetros!$B$11+(Parámetros!$B$8/100)*Parámetros!$B$12)+((Parámetros!$B$6/100)*Parámetros!$B$13+(Parámetros!$B$7/100)*Parámetros!$B$14+((100-Parámetros!$B$6-Parámetros!$B$7)/100)*Parámetros!$B$15)+Parámetros!$B$16))/Parámetros!$B$68+((H3*(((1-Parámetros!$B$8/100)*Parámetros!$B$11+(Parámetros!$B$8/100)*Parámetros!$B$12)+((Parámetros!$B$6/100)*Parámetros!$B$13+(Parámetros!$B$7/100)*Parámetros!$B$14+((100-Parámetros!$B$6-Parámetros!$B$7)/100)*Parámetros!$B$15)+Parámetros!$B$16))-(H3*(((1-Parámetros!$B$8/100)*Parámetros!$B$11+(Parámetros!$B$8/100)*Parámetros!$B$12)+((Parámetros!$B$6/100)*Parámetros!$B$13+(Parámetros!$B$7/100)*Parámetros!$B$14+((100-Parámetros!$B$6-Parámetros!$B$7)/100)*Parámetros!$B$15)+Parámetros!$B$16))*0/Parámetros!$B$68)*Parámetros!$B$66/100) | I37: =((C3*Parámetros!$B$67)/Parámetros!$B$68+((C3*Parámetros!$B$67)-(C3*Parámetros!$B$67)*6/Parámetros!$B$68)*Parámetros!$B$66/100)+((D3*Parámetros!$B$67)/Parámetros!$B$68+((D3*Parámetros!$B$67)-(D3*Parámetros!$B$67)*5/Parámetros!$B$68)*Parámetros!$B$66/100)+((E3*Parámetros!$B$67)/Parámetros!$B$68+((E3*Parámetros!$B$67)-(E3*Parámetros!$B$67)*4/Parámetros!$B$68)*Parámetros!$B$66/100)+((F3*(((1-Parámetros!$B$8/100)*Parámetros!$B$11+(Parámetros!$B$8/100)*Parámetros!$B$12)+((Parámetros!$B$6/100)*Parámetros!$B$13+(Parámetros!$B$7/100)*Parámetros!$B$14+((100-Parámetros!$B$6-Parámetros!$B$7)/100)*Parámetros!$B$15)+Parámetros!$B$16))/Parámetros!$B$68+((F3*(((1-Parámetros!$B$8/100)*Parámetros!$B$11+(Parámetros!$B$8/100)*Parámetros!$B$12)+((Parámetros!$B$6/100)*Parámetros!$B$13+(Parámetros!$B$7/100)*Parámetros!$B$14+((100-Parámetros!$B$6-Parámetros!$B$7)/100)*Parámetros!$B$15)+Parámetros!$B$16))-(F3*(((1-Parámetros!$B$8/100)*Parámetros!$B$11+(Parámetros!$B$8/100)*Parámetros!$B$12)+((Parámetros!$B$6/100)*Parámetros!$B$13+(Parámetros!$B$7/100)*Parámetros!$B$14+((100-Parámetros!$B$6-Parámetros!$B$7)/100)*Parámetros!$B$15)+Parámetros!$B$16))*3/Parámetros!$B$68)*Parámetros!$B$66/100)+((G3*(((1-Parámetros!$B$8/100)*Parámetros!$B$11+(Parámetros!$B$8/100)*Parámetros!$B$12)+((Parámetros!$B$6/100)*Parámetros!$B$13+(Parámetros!$B$7/100)*Parámetros!$B$14+((100-Parámetros!$B$6-Parámetros!$B$7)/100)*Parámetros!$B$15)+Parámetros!$B$16))/Parámetros!$B$68+((G3*(((1-Parámetros!$B$8/100)*Parámetros!$B$11+(Parámetros!$B$8/100)*Parámetros!$B$12)+((Parámetros!$B$6/100)*Parámetros!$B$13+(Parámetros!$B$7/100)*Parámetros!$B$14+((100-Parámetros!$B$6-Parámetros!$B$7)/100)*Parámetros!$B$15)+Parámetros!$B$16))-(G3*(((1-Parámetros!$B$8/100)*Parámetros!$B$11+(Parámetros!$B$8/100)*Parámetros!$B$12)+((Parámetros!$B$6/100)*Parámetros!$B$13+(Parámetros!$B$7/100)*Parámetros!$B$14+((100-Parámetros!$B$6-Parámetros!$B$7)/100)*Parámetros!$B$15)+Parámetros!$B$16))*2/Parámetros!$B$68)*Parámetros!$B$66/100)+((H3*(((1-Parámetros!$B$8/100)*Parámetros!$B$11+(Parámetros!$B$8/100)*Parámetros!$B$12)+((Parámetros!$B$6/100)*Parámetros!$B$13+(Parámetros!$B$7/100)*Parámetros!$B$14+((100-Parámetros!$B$6-Parámetros!$B$7)/100)*Parámetros!$B$15)+Parámetros!$B$16))/Parámetros!$B$68+((H3*(((1-Parámetros!$B$8/100)*Parámetros!$B$11+(Parámetros!$B$8/100)*Parámetros!$B$12)+((Parámetros!$B$6/100)*Parámetros!$B$13+(Parámetros!$B$7/100)*Parámetros!$B$14+((100-Parámetros!$B$6-Parámetros!$B$7)/100)*Parámetros!$B$15)+Parámetros!$B$16))-(H3*(((1-Parámetros!$B$8/100)*Parámetros!$B$11+(Parámetros!$B$8/100)*Parámetros!$B$12)+((Parámetros!$B$6/100)*Parámetros!$B$13+(Parámetros!$B$7/100)*Parámetros!$B$14+((100-Parámetros!$B$6-Parámetros!$B$7)/100)*Parámetros!$B$15)+Parámetros!$B$16))*1/Parámetros!$B$68)*Parámetros!$B$66/100)+((I3*(((1-Parámetros!$B$8/100)*Parámetros!$B$11+(Parámetros!$B$8/100)*Parámetros!$B$12)+((Parámetros!$B$6/100)*Parámetros!$B$13+(Parámetros!$B$7/100)*Parámetros!$B$14+((100-Parámetros!$B$6-Parámetros!$B$7)/100)*Parámetros!$B$15)+Parámetros!$B$16))/Parámetros!$B$68+((I3*(((1-Parámetros!$B$8/100)*Parámetros!$B$11+(Parámetros!$B$8/100)*Parámetros!$B$12)+((Parámetros!$B$6/100)*Parámetros!$B$13+(Parámetros!$B$7/100)*Parámetros!$B$14+((100-Parámetros!$B$6-Parámetros!$B$7)/100)*Parámetros!$B$15)+Parámetros!$B$16))-(I3*(((1-Parámetros!$B$8/100)*Parámetros!$B$11+(Parámetros!$B$8/100)*Parámetros!$B$12)+((Parámetros!$B$6/100)*Parámetros!$B$13+(Parámetros!$B$7/100)*Parámetros!$B$14+((100-Parámetros!$B$6-Parámetros!$B$7)/100)*Parámetros!$B$15)+Parámetros!$B$16))*0/Parámetros!$B$68)*Parámetros!$B$66/100) | J37: =((C3*Parámetros!$B$67)/Parámetros!$B$68+((C3*Parámetros!$B$67)-(C3*Parámetros!$B$67)*7/Parámetros!$B$68)*Parámetros!$B$66/100)+((D3*Parámetros!$B$67)/Parámetros!$B$68+((D3*Parámetros!$B$67)-(D3*Parámetros!$B$67)*6/Parámetros!$B$68)*Parámetros!$B$66/100)+((E3*Parámetros!$B$67)/Parámetros!$B$68+((E3*Parámetros!$B$67)-(E3*Parámetros!$B$67)*5/Parámetros!$B$68)*Parámetros!$B$66/100)+((F3*(((1-Parámetros!$B$8/100)*Parámetros!$B$11+(Parámetros!$B$8/100)*Parámetros!$B$12)+((Parámetros!$B$6/100)*Parámetros!$B$13+(Parámetros!$B$7/100)*Parámetros!$B$14+((100-Parámetros!$B$6-Parámetros!$B$7)/100)*Parámetros!$B$15)+Parámetros!$B$16))/Parámetros!$B$68+((F3*(((1-Parámetros!$B$8/100)*Parámetros!$B$11+(Parámetros!$B$8/100)*Parámetros!$B$12)+((Parámetros!$B$6/100)*Parámetros!$B$13+(Parámetros!$B$7/100)*Parámetros!$B$14+((100-Parámetros!$B$6-Parámetros!$B$7)/100)*Parámetros!$B$15)+Parámetros!$B$16))-(F3*(((1-Parámetros!$B$8/100)*Parámetros!$B$11+(Parámetros!$B$8/100)*Parámetros!$B$12)+((Parámetros!$B$6/100)*Parámetros!$B$13+(Parámetros!$B$7/100)*Parámetros!$B$14+((100-Parámetros!$B$6-Parámetros!$B$7)/100)*Parámetros!$B$15)+Parámetros!$B$16))*4/Parámetros!$B$68)*Parámetros!$B$66/100)+((G3*(((1-Parámetros!$B$8/100)*Parámetros!$B$11+(Parámetros!$B$8/100)*Parámetros!$B$12)+((Parámetros!$B$6/100)*Parámetros!$B$13+(Parámetros!$B$7/100)*Parámetros!$B$14+((100-Parámetros!$B$6-Parámetros!$B$7)/100)*Parámetros!$B$15)+Parámetros!$B$16))/Parámetros!$B$68+((G3*(((1-Parámetros!$B$8/100)*Parámetros!$B$11+(Parámetros!$B$8/100)*Parámetros!$B$12)+((Parámetros!$B$6/100)*Parámetros!$B$13+(Parámetros!$B$7/100)*Parámetros!$B$14+((100-Parámetros!$B$6-Parámetros!$B$7)/100)*Parámetros!$B$15)+Parámetros!$B$16))-(G3*(((1-Parámetros!$B$8/100)*Parámetros!$B$11+(Parámetros!$B$8/100)*Parámetros!$B$12)+((Parámetros!$B$6/100)*Parámetros!$B$13+(Parámetros!$B$7/100)*Parámetros!$B$14+((100-Parámetros!$B$6-Parámetros!$B$7)/100)*Parámetros!$B$15)+Parámetros!$B$16))*3/Parámetros!$B$68)*Parámetros!$B$66/100)+((H3*(((1-Parámetros!$B$8/100)*Parámetros!$B$11+(Parámetros!$B$8/100)*Parámetros!$B$12)+((Parámetros!$B$6/100)*Parámetros!$B$13+(Parámetros!$B$7/100)*Parámetros!$B$14+((100-Parámetros!$B$6-Parámetros!$B$7)/100)*Parámetros!$B$15)+Parámetros!$B$16))/Parámetros!$B$68+((H3*(((1-Parámetros!$B$8/100)*Parámetros!$B$11+(Parámetros!$B$8/100)*Parámetros!$B$12)+((Parámetros!$B$6/100)*Parámetros!$B$13+(Parámetros!$B$7/100)*Parámetros!$B$14+((100-Parámetros!$B$6-Parámetros!$B$7)/100)*Parámetros!$B$15)+Parámetros!$B$16))-(H3*(((1-Parámetros!$B$8/100)*Parámetros!$B$11+(Parámetros!$B$8/100)*Parámetros!$B$12)+((Parámetros!$B$6/100)*Parámetros!$B$13+(Parámetros!$B$7/100)*Parámetros!$B$14+((100-Parámetros!$B$6-Parámetros!$B$7)/100)*Parámetros!$B$15)+Parámetros!$B$16))*2/Parámetros!$B$68)*Parámetros!$B$66/100)+((I3*(((1-Parámetros!$B$8/100)*Parámetros!$B$11+(Parámetros!$B$8/100)*Parámetros!$B$12)+((Parámetros!$B$6/100)*Parámetros!$B$13+(Parámetros!$B$7/100)*Parámetros!$B$14+((100-Parámetros!$B$6-Parámetros!$B$7)/100)*Parámetros!$B$15)+Parámetros!$B$16))/Parámetros!$B$68+((I3*(((1-Parámetros!$B$8/100)*Parámetros!$B$11+(Parámetros!$B$8/100)*Parámetros!$B$12)+((Parámetros!$B$6/100)*Parámetros!$B$13+(Parámetros!$B$7/100)*Parámetros!$B$14+((100-Parámetros!$B$6-Parámetros!$B$7)/100)*Parámetros!$B$15)+Parámetros!$B$16))-(I3*(((1-Parámetros!$B$8/100)*Parámetros!$B$11+(Parámetros!$B$8/100)*Parámetros!$B$12)+((Parámetros!$B$6/100)*Parámetros!$B$13+(Parámetros!$B$7/100)*Parámetros!$B$14+((100-Parámetros!$B$6-Parámetros!$B$7)/100)*Parámetros!$B$15)+Parámetros!$B$16))*1/Parámetros!$B$68)*Parámetros!$B$66/100)+((J3*(((1-Parámetros!$B$8/100)*Parámetros!$B$11+(Parámetros!$B$8/100)*Parámetros!$B$12)+((Parámetros!$B$6/100)*Parámetros!$B$13+(Parámetros!$B$7/100)*Parámetros!$B$14+((100-Parámetros!$B$6-Parámetros!$B$7)/100)*Parámetros!$B$15)+Parámetros!$B$16))/Parámetros!$B$68+((J3*(((1-Parámetros!$B$8/100)*Parámetros!$B$11+(Parámetros!$B$8/100)*Parámetros!$B$12)+((Parámetros!$B$6/100)*Parámetros!$B$13+(Parámetros!$B$7/100)*Parámetros!$B$14+((100-Parámetros!$B$6-Parámetros!$B$7)/100)*Parámetros!$B$15)+Parámetros!$B$16))-(J3*(((1-Parámetros!$B$8/100)*Parámetros!$B$11+(Parámetros!$B$8/100)*Parámetros!$B$12)+((Parámetros!$B$6/100)*Parámetros!$B$13+(Parámetros!$B$7/100)*Parámetros!$B$14+((100-Parámetros!$B$6-Parámetros!$B$7)/100)*Parámetros!$B$15)+Parámetros!$B$16))*0/Parámetros!$B$68)*Parámetros!$B$66/100) | K37: =((C3*Parámetros!$B$67)/Parámetros!$B$68+((C3*Parámetros!$B$67)-(C3*Parámetros!$B$67)*8/Parámetros!$B$68)*Parámetros!$B$66/100)+((D3*Parámetros!$B$67)/Parámetros!$B$68+((D3*Parámetros!$B$67)-(D3*Parámetros!$B$67)*7/Parámetros!$B$68)*Parámetros!$B$66/100)+((E3*Parámetros!$B$67)/Parámetros!$B$68+((E3*Parámetros!$B$67)-(E3*Parámetros!$B$67)*6/Parámetros!$B$68)*Parámetros!$B$66/100)+((F3*(((1-Parámetros!$B$8/100)*Parámetros!$B$11+(Parámetros!$B$8/100)*Parámetros!$B$12)+((Parámetros!$B$6/100)*Parámetros!$B$13+(Parámetros!$B$7/100)*Parámetros!$B$14+((100-Parámetros!$B$6-Parámetros!$B$7)/100)*Parámetros!$B$15)+Parámetros!$B$16))/Parámetros!$B$68+((F3*(((1-Parámetros!$B$8/100)*Parámetros!$B$11+(Parámetros!$B$8/100)*Parámetros!$B$12)+((Parámetros!$B$6/100)*Parámetros!$B$13+(Parámetros!$B$7/100)*Parámetros!$B$14+((100-Parámetros!$B$6-Parámetros!$B$7)/100)*Parámetros!$B$15)+Parámetros!$B$16))-(F3*(((1-Parámetros!$B$8/100)*Parámetros!$B$11+(Parámetros!$B$8/100)*Parámetros!$B$12)+((Parámetros!$B$6/100)*Parámetros!$B$13+(Parámetros!$B$7/100)*Parámetros!$B$14+((100-Parámetros!$B$6-Parámetros!$B$7)/100)*Parámetros!$B$15)+Parámetros!$B$16))*5/Parámetros!$B$68)*Parámetros!$B$66/100)+((G3*(((1-Parámetros!$B$8/100)*Parámetros!$B$11+(Parámetros!$B$8/100)*Parámetros!$B$12)+((Parámetros!$B$6/100)*Parámetros!$B$13+(Parámetros!$B$7/100)*Parámetros!$B$14+((100-Parámetros!$B$6-Parámetros!$B$7)/100)*Parámetros!$B$15)+Parámetros!$B$16))/Parámetros!$B$68+((G3*(((1-Parámetros!$B$8/100)*Parámetros!$B$11+(Parámetros!$B$8/100)*Parámetros!$B$12)+((Parámetros!$B$6/100)*Parámetros!$B$13+(Parámetros!$B$7/100)*Parámetros!$B$14+((100-Parámetros!$B$6-Parámetros!$B$7)/100)*Parámetros!$B$15)+Parámetros!$B$16))-(G3*(((1-Parámetros!$B$8/100)*Parámetros!$B$11+(Parámetros!$B$8/100)*Parámetros!$B$12)+((Parámetros!$B$6/100)*Parámetros!$B$13+(Parámetros!$B$7/100)*Parámetros!$B$14+((100-Parámetros!$B$6-Parámetros!$B$7)/100)*Parámetros!$B$15)+Parámetros!$B$16))*4/Parámetros!$B$68)*Parámetros!$B$66/100)+((H3*(((1-Parámetros!$B$8/100)*Parámetros!$B$11+(Parámetros!$B$8/100)*Parámetros!$B$12)+((Parámetros!$B$6/100)*Parámetros!$B$13+(Parámetros!$B$7/100)*Parámetros!$B$14+((100-Parámetros!$B$6-Parámetros!$B$7)/100)*Parámetros!$B$15)+Parámetros!$B$16))/Parámetros!$B$68+((H3*(((1-Parámetros!$B$8/100)*Parámetros!$B$11+(Parámetros!$B$8/100)*Parámetros!$B$12)+((Parámetros!$B$6/100)*Parámetros!$B$13+(Parámetros!$B$7/100)*Parámetros!$B$14+((100-Parámetros!$B$6-Parámetros!$B$7)/100)*Parámetros!$B$15)+Parámetros!$B$16))-(H3*(((1-Parámetros!$B$8/100)*Parámetros!$B$11+(Parámetros!$B$8/100)*Parámetros!$B$12)+((Parámetros!$B$6/100)*Parámetros!$B$13+(Parámetros!$B$7/100)*Parámetros!$B$14+((100-Parámetros!$B$6-Parámetros!$B$7)/100)*Parámetros!$B$15)+Parámetros!$B$16))*3/Parámetros!$B$68)*Parámetros!$B$66/100)+((I3*(((1-Parámetros!$B$8/100)*Parámetros!$B$11+(Parámetros!$B$8/100)*Parámetros!$B$12)+((Parámetros!$B$6/100)*Parámetros!$B$13+(Parámetros!$B$7/100)*Parámetros!$B$14+((100-Parámetros!$B$6-Parámetros!$B$7)/100)*Parámetros!$B$15)+Parámetros!$B$16))/Parámetros!$B$68+((I3*(((1-Parámetros!$B$8/100)*Parámetros!$B$11+(Parámetros!$B$8/100)*Parámetros!$B$12)+((Parámetros!$B$6/100)*Parámetros!$B$13+(Parámetros!$B$7/100)*Parámetros!$B$14+((100-Parámetros!$B$6-Parámetros!$B$7)/100)*Parámetros!$B$15)+Parámetros!$B$16))-(I3*(((1-Parámetros!$B$8/100)*Parámetros!$B$11+(Parámetros!$B$8/100)*Parámetros!$B$12)+((Parámetros!$B$6/100)*Parámetros!$B$13+(Parámetros!$B$7/100)*Parámetros!$B$14+((100-Parámetros!$B$6-Parámetros!$B$7)/100)*Parámetros!$B$15)+Parámetros!$B$16))*2/Parámetros!$B$68)*Parámetros!$B$66/100)+((J3*(((1-Parámetros!$B$8/100)*Parámetros!$B$11+(Parámetros!$B$8/100)*Parámetros!$B$12)+((Parámetros!$B$6/100)*Parámetros!$B$13+(Parámetros!$B$7/100)*Parámetros!$B$14+((100-Parámetros!$B$6-Parámetros!$B$7)/100)*Parámetros!$B$15)+Parámetros!$B$16))/Parámetros!$B$68+((J3*(((1-Parámetros!$B$8/100)*Parámetros!$B$11+(Parámetros!$B$8/100)*Parámetros!$B$12)+((Parámetros!$B$6/100)*Parámetros!$B$13+(Parámetros!$B$7/100)*Parámetros!$B$14+((100-Parámetros!$B$6-Parámetros!$B$7)/100)*Parámetros!$B$15)+Parámetros!$B$16))-(J3*(((1-Parámetros!$B$8/100)*Parámetros!$B$11+(Parámetros!$B$8/100)*Parámetros!$B$12)+((Parámetros!$B$6/100)*Parámetros!$B$13+(Parámetros!$B$7/100)*Parámetros!$B$14+((100-Parámetros!$B$6-Parámetros!$B$7)/100)*Parámetros!$B$15)+Parámetros!$B$16))*1/Parámetros!$B$68)*Parámetros!$B$66/100)+((K3*(((1-Parámetros!$B$8/100)*Parámetros!$B$11+(Parámetros!$B$8/100)*Parámetros!$B$12)+((Parámetros!$B$6/100)*Parámetros!$B$13+(Parámetros!$B$7/100)*Parámetros!$B$14+((100-Parámetros!$B$6-Parámetros!$B$7)/100)*Parámetros!$B$15)+Parámetros!$B$16))/Parámetros!$B$68+((K3*(((1-Parámetros!$B$8/100)*Parámetros!$B$11+(Parámetros!$B$8/100)*Parámetros!$B$12)+((Parámetros!$B$6/100)*Parámetros!$B$13+(Parámetros!$B$7/100)*Parámetros!$B$14+((100-Parámetros!$B$6-Parámetros!$B$7)/100)*Parámetros!$B$15)+Parámetros!$B$16))-(K3*(((1-Parámetros!$B$8/100)*Parámetros!$B$11+(Parámetros!$B$8/100)*Parámetros!$B$12)+((Parámetros!$B$6/100)*Parámetros!$B$13+(Parámetros!$B$7/100)*Parámetros!$B$14+((100-Parámetros!$B$6-Parámetros!$B$7)/100)*Parámetros!$B$15)+Parámetros!$B$16))*0/Parámetros!$B$68)*Parámetros!$B$66/100) | L37: =((C3*Parámetros!$B$67)/Parámetros!$B$68+((C3*Parámetros!$B$67)-(C3*Parámetros!$B$67)*9/Parámetros!$B$68)*Parámetros!$B$66/100)+((D3*Parámetros!$B$67)/Parámetros!$B$68+((D3*Parámetros!$B$67)-(D3*Parámetros!$B$67)*8/Parámetros!$B$68)*Parámetros!$B$66/100)+((E3*Parámetros!$B$67)/Parámetros!$B$68+((E3*Parámetros!$B$67)-(E3*Parámetros!$B$67)*7/Parámetros!$B$68)*Parámetros!$B$66/100)+((F3*(((1-Parámetros!$B$8/100)*Parámetros!$B$11+(Parámetros!$B$8/100)*Parámetros!$B$12)+((Parámetros!$B$6/100)*Parámetros!$B$13+(Parámetros!$B$7/100)*Parámetros!$B$14+((100-Parámetros!$B$6-Parámetros!$B$7)/100)*Parámetros!$B$15)+Parámetros!$B$16))/Parámetros!$B$68+((F3*(((1-Parámetros!$B$8/100)*Parámetros!$B$11+(Parámetros!$B$8/100)*Parámetros!$B$12)+((Parámetros!$B$6/100)*Parámetros!$B$13+(Parámetros!$B$7/100)*Parámetros!$B$14+((100-Parámetros!$B$6-Parámetros!$B$7)/100)*Parámetros!$B$15)+Parámetros!$B$16))-(F3*(((1-Parámetros!$B$8/100)*Parámetros!$B$11+(Parámetros!$B$8/100)*Parámetros!$B$12)+((Parámetros!$B$6/100)*Parámetros!$B$13+(Parámetros!$B$7/100)*Parámetros!$B$14+((100-Parámetros!$B$6-Parámetros!$B$7)/100)*Parámetros!$B$15)+Parámetros!$B$16))*6/Parámetros!$B$68)*Parámetros!$B$66/100)+((G3*(((1-Parámetros!$B$8/100)*Parámetros!$B$11+(Parámetros!$B$8/100)*Parámetros!$B$12)+((Parámetros!$B$6/100)*Parámetros!$B$13+(Parámetros!$B$7/100)*Parámetros!$B$14+((100-Parámetros!$B$6-Parámetros!$B$7)/100)*Parámetros!$B$15)+Parámetros!$B$16))/Parámetros!$B$68+((G3*(((1-Parámetros!$B$8/100)*Parámetros!$B$11+(Parámetros!$B$8/100)*Parámetros!$B$12)+((Parámetros!$B$6/100)*Parámetros!$B$13+(Parámetros!$B$7/100)*Parámetros!$B$14+((100-Parámetros!$B$6-Parámetros!$B$7)/100)*Parámetros!$B$15)+Parámetros!$B$16))-(G3*(((1-Parámetros!$B$8/100)*Parámetros!$B$11+(Parámetros!$B$8/100)*Parámetros!$B$12)+((Parámetros!$B$6/100)*Parámetros!$B$13+(Parámetros!$B$7/100)*Parámetros!$B$14+((100-Parámetros!$B$6-Parámetros!$B$7)/100)*Parámetros!$B$15)+Parámetros!$B$16))*5/Parámetros!$B$68)*Parámetros!$B$66/100)+((H3*(((1-Parámetros!$B$8/100)*Parámetros!$B$11+(Parámetros!$B$8/100)*Parámetros!$B$12)+((Parámetros!$B$6/100)*Parámetros!$B$13+(Parámetros!$B$7/100)*Parámetros!$B$14+((100-Parámetros!$B$6-Parámetros!$B$7)/100)*Parámetros!$B$15)+Parámetros!$B$16))/Parámetros!$B$68+((H3*(((1-Parámetros!$B$8/100)*Parámetros!$B$11+(Parámetros!$B$8/100)*Parámetros!$B$12)+((Parámetros!$B$6/100)*Parámetros!$B$13+(Parámetros!$B$7/100)*Parámetros!$B$14+((100-Parámetros!$B$6-Parámetros!$B$7)/100)*Parámetros!$B$15)+Parámetros!$B$16))-(H3*(((1-Parámetros!$B$8/100)*Parámetros!$B$11+(Parámetros!$B$8/100)*Parámetros!$B$12)+((Parámetros!$B$6/100)*Parámetros!$B$13+(Parámetros!$B$7/100)*Parámetros!$B$14+((100-Parámetros!$B$6-Parámetros!$B$7)/100)*Parámetros!$B$15)+Parámetros!$B$16))*4/Parámetros!$B$68)*Parámetros!$B$66/100)+((I3*(((1-Parámetros!$B$8/100)*Parámetros!$B$11+(Parámetros!$B$8/100)*Parámetros!$B$12)+((Parámetros!$B$6/100)*Parámetros!$B$13+(Parámetros!$B$7/100)*Parámetros!$B$14+((100-Parámetros!$B$6-Parámetros!$B$7)/100)*Parámetros!$B$15)+Parámetros!$B$16))/Parámetros!$B$68+((I3*(((1-Parámetros!$B$8/100)*Parámetros!$B$11+(Parámetros!$B$8/100)*Parámetros!$B$12)+((Parámetros!$B$6/100)*Parámetros!$B$13+(Parámetros!$B$7/100)*Parámetros!$B$14+((100-Parámetros!$B$6-Parámetros!$B$7)/100)*Parámetros!$B$15)+Parámetros!$B$16))-(I3*(((1-Parámetros!$B$8/100)*Parámetros!$B$11+(Parámetros!$B$8/100)*Parámetros!$B$12)+((Parámetros!$B$6/100)*Parámetros!$B$13+(Parámetros!$B$7/100)*Parámetros!$B$14+((100-Parámetros!$B$6-Parámetros!$B$7)/100)*Parámetros!$B$15)+Parámetros!$B$16))*3/Parámetros!$B$68)*Parámetros!$B$66/100)+((J3*(((1-Parámetros!$B$8/100)*Parámetros!$B$11+(Parámetros!$B$8/100)*Parámetros!$B$12)+((Parámetros!$B$6/100)*Parámetros!$B$13+(Parámetros!$B$7/100)*Parámetros!$B$14+((100-Parámetros!$B$6-Parámetros!$B$7)/100)*Parámetros!$B$15)+Parámetros!$B$16))/Parámetros!$B$68+((J3*(((1-Parámetros!$B$8/100)*Parámetros!$B$11+(Parámetros!$B$8/100)*Parámetros!$B$12)+((Parámetros!$B$6/100)*Parámetros!$B$13+(Parámetros!$B$7/100)*Parámetros!$B$14+((100-Parámetros!$B$6-Parámetros!$B$7)/100)*Parámetros!$B$15)+Parámetros!$B$16))-(J3*(((1-Parámetros!$B$8/100)*Parámetros!$B$11+(Parámetros!$B$8/100)*Parámetros!$B$12)+((Parámetros!$B$6/100)*Parámetros!$B$13+(Parámetros!$B$7/100)*Parámetros!$B$14+((100-Parámetros!$B$6-Parámetros!$B$7)/100)*Parámetros!$B$15)+Parámetros!$B$16))*2/Parámetros!$B$68)*Parámetros!$B$66/100)+((K3*(((1-Parámetros!$B$8/100)*Parámetros!$B$11+(Parámetros!$B$8/100)*Parámetros!$B$12)+((Parámetros!$B$6/100)*Parámetros!$B$13+(Parámetros!$B$7/100)*Parámetros!$B$14+((100-Parámetros!$B$6-Parámetros!$B$7)/100)*Parámetros!$B$15)+Parámetros!$B$16))/Parámetros!$B$68+((K3*(((1-Parámetros!$B$8/100)*Parámetros!$B$11+(Parámetros!$B$8/100)*Parámetros!$B$12)+((Parámetros!$B$6/100)*Parámetros!$B$13+(Parámetros!$B$7/100)*Parámetros!$B$14+((100-Parámetros!$B$6-Parámetros!$B$7)/100)*Parámetros!$B$15)+Parámetros!$B$16))-(K3*(((1-Parámetros!$B$8/100)*Parámetros!$B$11+(Parámetros!$B$8/100)*Parámetros!$B$12)+((Parámetros!$B$6/100)*Parámetros!$B$13+(Parámetros!$B$7/100)*Parámetros!$B$14+((100-Parámetros!$B$6-Parámetros!$B$7)/100)*Parámetros!$B$15)+Parámetros!$B$16))*1/Parámetros!$B$68)*Parámetros!$B$66/100)+((L3*(((1-Parámetros!$B$8/100)*Parámetros!$B$11+(Parámetros!$B$8/100)*Parámetros!$B$12)+((Parámetros!$B$6/100)*Parámetros!$B$13+(Parámetros!$B$7/100)*Parámetros!$B$14+((100-Parámetros!$B$6-Parámetros!$B$7)/100)*Parámetros!$B$15)+Parámetros!$B$16))/Parámetros!$B$68+((L3*(((1-Parámetros!$B$8/100)*Parámetros!$B$11+(Parámetros!$B$8/100)*Parámetros!$B$12)+((Parámetros!$B$6/100)*Parámetros!$B$13+(Parámetros!$B$7/100)*Parámetros!$B$14+((100-Parámetros!$B$6-Parámetros!$B$7)/100)*Parámetros!$B$15)+Parámetros!$B$16))-(L3*(((1-Parámetros!$B$8/100)*Parámetros!$B$11+(Parámetros!$B$8/100)*Parámetros!$B$12)+((Parámetros!$B$6/100)*Parámetros!$B$13+(Parámetros!$B$7/100)*Parámetros!$B$14+((100-Parámetros!$B$6-Parámetros!$B$7)/100)*Parámetros!$B$15)+Parámetros!$B$16))*0/Parámetros!$B$68)*Parámetros!$B$66/100)
A38: INGRESOS VAD TOTALES | B38: =B36+B37 | C38: =C36+C37 | D38: =D36+D37 | E38: =E36+E37 | F38: =F36+F37 | G38: =G36+G37 | H38: =H36+H37 | I38: =I36+I37 | ... L38: =L36+L37
A40: FLUJO DE CAJA
A41: Flujo de Caja Libre (FCF) | B41: =B33+B38-B20-B12 | C41: =C33+C38-C20-C12 | D41: =D33+D38-D20-D12 | E41: =E33+E38-E20-E12 | F41: =F33+F38-F20-F12 | G41: =G33+G38-G20-G12 | H41: =H33+H38-H20-H12 | I41: =I33+I38-I20-I12 | ... L41: =L33+L38-L20-L12
A42: └ FCF Descontado al WACC del Proyecto | B42: =B41/(1+Parámetros!$B$5/100)^0 | C42: =C41/(1+Parámetros!$B$5/100)^1 | D42: =D41/(1+Parámetros!$B$5/100)^2 | E42: =E41/(1+Parámetros!$B$5/100)^3 | F42: =F41/(1+Parámetros!$B$5/100)^4 | G42: =G41/(1+Parámetros!$B$5/100)^5 | H42: =H41/(1+Parámetros!$B$5/100)^6 | I42: =I41/(1+Parámetros!$B$5/100)^7 | J42: =J41/(1+Parámetros!$B$5/100)^8 | K42: =K41/(1+Parámetros!$B$5/100)^9 | L42: =L41/(1+Parámetros!$B$5/100)^10
A43: └ VPN Acumulado | B43: =B42 | C43: =SUM(B42:C42) | D43: =SUM(B42:D42) | E43: =SUM(B42:E42) | F43: =SUM(B42:F42) | G43: =SUM(B42:G42) | H43: =SUM(B42:H42) | I43: =SUM(B42:I42) | J43: =SUM(B42:J42) | K43: =SUM(B42:K42) | L43: =SUM(B42:L42)

Sheet Indicadores
A1: 📊 INDICADORES FINANCIEROS — AMI Baseline (Edesur 2026)
A3: Horizonte: 10 años | WACC: 14.2% | Medidores: 2.700.000 | Curva: Lineal
A5: 1. VALOR PRESENTE NETO (VPN)
A6: VPN del Proyecto | B6: ='Flujo de Fondos'!L43 | C6: Suma de todos los FCF anuales descontados al WACC (14.2%). Un VPN > 0 indica que el proyecto crea valor por encima del costo de capital.
A7: └ CAPEX Total Nominal (sin descontar) | B7: =SUM('Flujo de Fondos'!B12:L12) | C7: Inversión total ejecutada a lo largo del horizonte.
A8: └ OPEX Total Nominal (sin descontar) | B8: =SUM('Flujo de Fondos'!B20:L20) | C8: Costos operativos acumulados del proyecto.
A9: └ Beneficios Totales Nominales | B9: =SUM('Flujo de Fondos'!B33:L33) | C9: Suma de todos los savings operacionales y regulatorios (sin descontar).
A10: └ Ingresos VAD Totales Nominales | B10: =SUM('Flujo de Fondos'!B38:L38) | C10: Flujos de ingreso tarifario reconocidos por el ENRE (sin descontar).
A12: 2. TASA INTERNA DE RETORNO (TIR / IRR)
A13: TIR del Proyecto | B13: =IRR('Flujo de Fondos'!B41:L41) | C13: Tasa que hace el VPN = 0. Se calcula con IRR() de Excel sobre los FCF anuales (Año 0 a Año 10). Debe compararse contra el WACC (14.2%): TIR > WACC → proyecto viable.
A14: └ WACC del Proyecto (umbral mínimo) | B14: =Parámetros!$B$5 | C14: Si TIR > WACC → el proyecto supera el costo de capital.
A15: └ Spread TIR - WACC | B15: =IRR('Flujo de Fondos'!B41:L41)-Parámetros!$B$5/100 | C15: Cuánto supera la TIR al costo de capital. Spread positivo = creación de valor.
A17: 3. RETORNO SOBRE LA INVERSIÓN (ROI)
A18: ROI Nominal del Proyecto | B18: =((SUM('Flujo de Fondos'!B33:L33)+SUM('Flujo de Fondos'!B38:L38)-SUM('Flujo de Fondos'!B20:L20))-SUM('Flujo de Fondos'!B12:L12))/SUM('Flujo de Fondos'!B12:L12) | C18: ROI = (Ingresos Totales Netos de OPEX - CAPEX Total) / CAPEX Total. Mide cuánto retorna el proyecto sobre cada USD invertido, en términos nominales (sin descontar).
A19: └ Total Ingresos Netos de OPEX (nominales) | B19: =(SUM('Flujo de Fondos'!B33:L33)+SUM('Flujo de Fondos'!B38:L38)-SUM('Flujo de Fondos'!B20:L20)) | C19: Suma de Beneficios + VAD - OPEX a lo largo de todo el horizonte.
A20: └ Total CAPEX (nominal) | B20: =SUM('Flujo de Fondos'!B12:L12) | C20: Inversión total ejecutada.
A22: 4. ÍNDICE DE RENTABILIDAD (Profitability Index — PI)
A23: Profitability Index (PI) | B23: =('Flujo de Fondos'!L43+('Flujo de Fondos'!B12/(1+Parámetros!$B$5/100)^0+'Flujo de Fondos'!C12/(1+Parámetros!$B$5/100)^1+'Flujo de Fondos'!D12/(1+Parámetros!$B$5/100)^2+'Flujo de Fondos'!E12/(1+Parámetros!$B$5/100)^3+'Flujo de Fondos'!F12/(1+Parámetros!$B$5/100)^4+'Flujo de Fondos'!G12/(1+Parámetros!$B$5/100)^5+'Flujo de Fondos'!H12/(1+Parámetros!$B$5/100)^6+'Flujo de Fondos'!I12/(1+Parámetros!$B$5/100)^7+'Flujo de Fondos'!J12/(1+Parámetros!$B$5/100)^8+'Flujo de Fondos'!K12/(1+Parámetros!$B$5/100)^9+'Flujo de Fondos'!L12/(1+Parámetros!$B$5/100)^10))/('Flujo de Fondos'!B12/(1+Parámetros!$B$5/100)^0+'Flujo de Fondos'!C12/(1+Parámetros!$B$5/100)^1+'Flujo de Fondos'!D12/(1+Parámetros!$B$5/100)^2+'Flujo de Fondos'!E12/(1+Parámetros!$B$5/100)^3+'Flujo de Fondos'!F12/(1+Parámetros!$B$5/100)^4+'Flujo de Fondos'!G12/(1+Parámetros!$B$5/100)^5+'Flujo de Fondos'!H12/(1+Parámetros!$B$5/100)^6+'Flujo de Fondos'!I12/(1+Parámetros!$B$5/100)^7+'Flujo de Fondos'!J12/(1+Parámetros!$B$5/100)^8+'Flujo de Fondos'!K12/(1+Parámetros!$B$5/100)^9+'Flujo de Fondos'!L12/(1+Parámetros!$B$5/100)^10) | C23: PI = VP(Ingresos Netos) / VP(CAPEX). PI > 1 indica que el valor presente de los ingresos supera el valor presente de las inversiones. Un PI = 1.3 significa que por cada USD invertido, se generan USD 1.30 en valor descontado.
A24: └ VP del CAPEX Total (descontado) | B24: =('Flujo de Fondos'!B12/(1+Parámetros!$B$5/100)^0+'Flujo de Fondos'!C12/(1+Parámetros!$B$5/100)^1+'Flujo de Fondos'!D12/(1+Parámetros!$B$5/100)^2+'Flujo de Fondos'!E12/(1+Parámetros!$B$5/100)^3+'Flujo de Fondos'!F12/(1+Parámetros!$B$5/100)^4+'Flujo de Fondos'!G12/(1+Parámetros!$B$5/100)^5+'Flujo de Fondos'!H12/(1+Parámetros!$B$5/100)^6+'Flujo de Fondos'!I12/(1+Parámetros!$B$5/100)^7+'Flujo de Fondos'!J12/(1+Parámetros!$B$5/100)^8+'Flujo de Fondos'!K12/(1+Parámetros!$B$5/100)^9+'Flujo de Fondos'!L12/(1+Parámetros!$B$5/100)^10) | C24: Valor presente de todas las inversiones de capital.
A25: └ VP de Ingresos Netos (descontado) | B25: ='Flujo de Fondos'!L43+('Flujo de Fondos'!B12/(1+Parámetros!$B$5/100)^0+'Flujo de Fondos'!C12/(1+Parámetros!$B$5/100)^1+'Flujo de Fondos'!D12/(1+Parámetros!$B$5/100)^2+'Flujo de Fondos'!E12/(1+Parámetros!$B$5/100)^3+'Flujo de Fondos'!F12/(1+Parámetros!$B$5/100)^4+'Flujo de Fondos'!G12/(1+Parámetros!$B$5/100)^5+'Flujo de Fondos'!H12/(1+Parámetros!$B$5/100)^6+'Flujo de Fondos'!I12/(1+Parámetros!$B$5/100)^7+'Flujo de Fondos'!J12/(1+Parámetros!$B$5/100)^8+'Flujo de Fondos'!K12/(1+Parámetros!$B$5/100)^9+'Flujo de Fondos'!L12/(1+Parámetros!$B$5/100)^10) | C25: VP(Beneficios + VAD - OPEX).
A27: 5. PERÍODO DE RECUPERO (Payback)
A28: Año | B28: FCF Año | C28: FCF Acumulado (nominal) | D28: FCF Acumulado (descontado)
A29: Año 0 | B29: ='Flujo de Fondos'!B41 | C29: ='Flujo de Fondos'!B41 | D29: ='Flujo de Fondos'!B42
A30: Año 1 | B30: ='Flujo de Fondos'!C41 | C30: =C29+'Flujo de Fondos'!C41 | D30: =D29+'Flujo de Fondos'!C42
A31: Año 2 | B31: ='Flujo de Fondos'!D41 | C31: =C30+'Flujo de Fondos'!D41 | D31: =D30+'Flujo de Fondos'!D42
A32: Año 3 | B32: ='Flujo de Fondos'!E41 | C32: =C31+'Flujo de Fondos'!E41 | D32: =D31+'Flujo de Fondos'!E42
A33: Año 4 | B33: ='Flujo de Fondos'!F41 | C33: =C32+'Flujo de Fondos'!F41 | D33: =D32+'Flujo de Fondos'!F42
A34: Año 5 | B34: ='Flujo de Fondos'!G41 | C34: =C33+'Flujo de Fondos'!G41 | D34: =D33+'Flujo de Fondos'!G42
A35: Año 6 | B35: ='Flujo de Fondos'!H41 | C35: =C34+'Flujo de Fondos'!H41 | D35: =D34+'Flujo de Fondos'!H42
A36: Año 7 | B36: ='Flujo de Fondos'!I41 | C36: =C35+'Flujo de Fondos'!I41 | D36: =D35+'Flujo de Fondos'!I42
A37: Año 8 | B37: ='Flujo de Fondos'!J41 | C37: =C36+'Flujo de Fondos'!J41 | D37: =D36+'Flujo de Fondos'!J42
A38: Año 9 | B38: ='Flujo de Fondos'!K41 | C38: =C37+'Flujo de Fondos'!K41 | D38: =D37+'Flujo de Fondos'!K42
A39: Año 10 | B39: ='Flujo de Fondos'!L41 | C39: =C38+'Flujo de Fondos'!L41 | D39: =D38+'Flujo de Fondos'!L42
A41: Payback Simple (años) | B41: =MATCH(TRUE,C29:C39>=0,0)-1 | C41: Primer año en el que el FCF acumulado nominal es mayor o igual a cero. Indica cuándo se recupera la inversión en términos corrientes.
A42: Payback Descontado (años) | B42: =MATCH(TRUE,D29:D39>=0,0)-1 | C42: Primer año en el que el VPN acumulado (FCF descontado al WACC) es mayor o igual a cero. Es el indicador más conservador de recupero.
A44: 6. MÉTRICAS UNITARIAS POR MEDIDOR
A45: CAPEX por Medidor (promedio) | B45: =SUM('Flujo de Fondos'!B12:L12)/Parámetros!$B$3 | C45: Costo de inversión total dividido por el total de medidores instalados. Incluye hardware, instalación, IT e infraestructura.
A46: Beneficio por Medidor (régimen anual) | B46: =(SUM('Flujo de Fondos'!B33:L33)+SUM('Flujo de Fondos'!B38:L38))/Parámetros!$B$3/Parámetros!$B$4 | C46: Savings anuales en régimen por cada medidor activo en la red. Mide la "productividad económica" de cada punto de medición.
A47: OPEX por Medidor en Régimen | B47: =SUM('Flujo de Fondos'!B20:L20)/Parámetros!$B$3/Parámetros!$B$4 | C47: Costo operativo anual por medidor activo (telecom, cloud, mantenimiento, etc.).
A49: 7. RESUMEN EJECUTIVO — SEMÁFORO
...
